Workbook

Sheet Cont Dir
A1: Puerto | B1: Fech pedido | C1: Tipo Papa | D1: Cliente | F1: Fech Fact | G1: Total fact | H1: T.C. Euros en pedimento | I1: ETD | J1: ETA | K1: Pedido | L1: # Cont | M1: Clte | N1: Estatus | O1: Factura | P1: Entrega | Q1: Vencim Fact | R1: Pago | S1: TC Pagado | T1: Dif | U1: COMENTARIOS | V1: UTILIDAD O PERDIDA CAMBIARIA
A2: Altamira | B2: 45792 | C2: Castel | F2: 45811 | G2: 24840 | I2: 45819 | J2: 45841 | K2: 25-617 | L2: C-406 | M2: ALT-CDMX | N2: Proforma | O2: Proforma | Q2: =+F2+60 -> 45871 | U2: CASTEL 10 EUR
A3: Veracruz | B3: 45792 | C3: Castel | D3: Nico / Oaxaca | F3: 45804 | G3: 24840 | I3: 45812 | J3: 45831 | K3: 25-618 | L3: C-407 | M3: VER-NICHOLAS SELUAN | N3: Proforma | O3: Proforma | Q3: =+F3+60 -> 45864 | U3: CASTEL 10 EUR
A4: Altamira | B4: 45803 | C4: 102013 | D4: Gpo Ruiz GDL | E4: 305
A5: Altamira | B5: 45802 | C5: W Light Cover
B6: China

Sheet Cont. Completos
A2: Puerto | B2: Fech pedido | C2: Fech Fact | D2: Total fact | E2: T.C. Euros en pedimento | F2: ETD | H2: Pedido | I2: # Cont
A3: Altamira | B3: 45792 | C3: 45811 | D3: 24840 | F3: 45819 | H3: 25-617 | I3: C-406
A4: Veracruz | B4: 45792 | C4: 45804 | D4: 24840 | F4: 45812 | H4: 25-618 | I4: C-407
A5: Altamira | B5: 45819 | C5: 45831 | D5: 24840 | F5: 45840 | H5: 25-619 | I5: C-408

Sheet Contenedores
H2: Buscar Contenedor | I2: COTENEDOR | J2: Clte | K2: Estatus | L2: Factura | M2: Entrega | N2: Vencim Fact | O2: Fecha Pago | P2: TC Pagado
I3: C-102 | J3: =VLOOKUP($I$3,Contenedores!$I$7:$P$323,2,0) -> ABASTOS LOGICOS | K3: =VLOOKUP($I$3,Contenedores!$I$7:$P$323,3,0) -> Confirmado | L3: =VLOOKUP($I$3,Contenedores!$I$7:$P$323,4,0) -> 25163880 | M3: =VLOOKUP($I$3,Contenedores!$I$7:$P$323,5,0) -> 46024 | N3: =VLOOKUP($I$3,Contenedores!$I$7:$P$323,6,0) -> 46005 | O3: =VLOOKUP($I$3,Contenedores!$I$7:$P$323,7,0) -> 46005 | P3: =VLOOKUP($I$3,Contenedores!$I$7:$P$323,8,0) -> 21.21
A6: AVIKO | P6: FORWARD
A7: Puerto | B7: Fech pedido | C7: Fech Fact | D7: Total fact | E7: T.C. Euros en pedimento | F7: ETD | G7: ETA | H7: Pedido | I7: # Cont | J7: Clte | K7: Estatus | L7: Factura | M7: Entrega | N7: Vencim Fact | O7: Pago | P7: TC Pagado | Q7: Dif | R7: COMENTARIOS | S7: UTILIDAD O PERDIDA CAMBIARIA
A8: Veracruz | B8: 44434 | F8: 44475 | G8: 44494 | H8: 21-503 | I8: C-292 | J8: 3TD | K8: Entregado | L8: 92752190 | M8: 44499 | N8: 44529 | O8: 44529
A9: Progreso | B9: 44434 | F9: 44464 | G9: 44486 | H9: 21-502 | I9: C-291 | J9: ABASTOS LOG | K9: Entregado | L9: 92748302 | M9: 44491 | N9: 44521 | O9: 44522
A10: Veracruz | B10: 44425 | F10: 44475 | G10: 44492 | H10: 21-501 | I10: C-290 A | J10: 3B | K10: Entregado | L10: 92744649 | M10: 44492 | N10: 44533 | O10: 44516
A11: Veracruz | B11: 44425 | F11: 44475 | G11: 44508 | H11: 21-501 | I11: C-290 B | J11: 3B | K11: Entregado | L11: 92753335 | M11: 44513 | N11: 44533 | O11: 44564
A12: Veracruz | B12: 44434 | F12: =G12-20 -> 44494 | G12: 44514 | H12: 21-505 | I12: C-294 | J12: 3B | K12: Entregado | L12: 92763242 | M12: 44525 | N12: 44554 | O12: 44554
A13: Progreso | B13: 44434 | F13: =G13-21 -> 44486 | G13: 44507 | H13: 21-506 | I13: C-295 | J13: ABASTOS LOG | K13: Entregado | L13: 92758835 | M13: 44513 | N13: 44543 | O13: 44510
A14: Veracruz | B14: 44434 | F14: =G14-20 -> 44498 | G14: 44518 | H14: 21-508 | I14: C-297 | J14: 3TD | K14: Entregado | L14: 92761538 | M14: 44525 | N14: 44549
A15: Veracruz | B15: 44434 | C15: 44533 | F15: 44540 | G15: 44572 | H15: 21-510 | I15: C-299 | J15: 3B | K15: Entregado | L15: 92781508 | M15: 44580 | N15: =+C15+60 -> 44593 | O15: 44594
A16: Progreso | B16: 44532 | C16: 44532 | F16: 44538 | G16: 44572 | H16: 21-511 | I16: C-300 | J16: ABASTOS LOG | K16: Entregado | L16: 92781106 | M16: 44575 | N16: =+C16+60 -> 44592 | O16: 44592
A17: Veracruz | B17: 44434 | C17: 44533 | F17: 44540 | G17: 44572 | H17: 21-513 | I17: C-302 | J17: 3TD | K17: Entregado | L17: 92781453 | M17: 44582 | N17: =+C17+60 -> 44593 | O17: 44595
A18: Progreso | B18: 44434 | C18: 44539 | F18: 44545 | G18: 44590 | H18: 21-514 | I18: C-303 | J18: ABASTOS LOG | K18: Entregado | L18: 92784317 | M18: 44595 | N18: =+C18+60 -> 44599 | O18: 44601
A19: Veracruz | B19: 44434 | C19: 44565 | F19: 44573 | G19: 44594 | H19: 21-515 | I19: C-304 | J19: 3B | K19: Entregado | L19: 92793939 | M19: 44603 | N19: =+C19+60 -> 44625 | O19: 44627
A20: Veracruz | B20: 44449 | F20: 44482 | G20: 44508 | H20: 21-516 | I20: C-305 | J20: 3TD | K20: Entregado | L20: 92753341 | M20: 44513 | N20: =+C20+60 -> 60 | O20: 44536
A21: Veracruz | B21: 44512 | C21: 44571 | F21: 44587 | G21: 44622 | H21: 21-519 | I21: C-308 | J21: 3B | K21: Entregado | L21: 92796168 | M21: 44630 | N21: =+C21+60 -> 44631 | O21: 44634
A22: Veracruz | B22: 44512 | C22: 44537 | F22: 44544 | G22: 44571 | H22: 21-518 | I22: C-307 | J22: 3TD | K22: Entregado | L22: 92782952 | M22: 44579 | N22: =+C22+60 -> 44597 | O22: 44600
A23: Veracruz | B23: 44532 | C23: 44574 | F23: 44580 | G23: 44622 | H23: 21-520 | I23: C-309 | J23: 3B | K23: Entregado | L23: 92798101 | M23: 44632 | N23: =+C23+60 -> 44634 | O23: 44638
A24: Veracruz | B24: 44532 | C24: 44592 | F24: 44618 | G24: 44654 | H24: 21-521 | I24: C-310 | J24: 3B | K24: Confirmado | L24: 92805982 | M24: 44664 | N24: =+C24+60 -> 44652 | O24: 44670
A25: Veracruz | B25: 44538 | C25: 44573 | F25: 44587 | G25: 44622 | H25: 21-522 | I25: C-311 | J25: LA COMER | K25: Entregado | L25: 92797446 | M25: 44632 | N25: =+C25+60 -> 44633 | O25: 44635
A26: Veracruz | B26: 44581 | C26: 44643 | F26: 44667 | G26: 44692 | H26: 22-523 | I26: C-312 | J26: SONORA | K26: Confirmado | L26: 92831908 | M26: 44698 | N26: =+C26+60 -> 44703 | O26: 44715
A27: Veracruz | B27: 44602 | C27: 44623 | F27: 44622 | G27: 44648 | H27: 22-524 | I27: C-313 | J27: 3B | K27: Confirmado | L27: 92821407 | M27: 44656 | N27: =+C27+60 -> 44683 | O27: 44685
A28: Veracruz | B28: 44602 | C28: 44670 | F28: 44697 | G28: 44739 | H28: 22-525 | I28: C-314 | J28: 3B | K28: Confirmado | L28: 92864149 | M28: 44747 | N28: =+C28+60 -> 44730 | O28: 44750 | P28: INFO ACTUALIZADA AL 08/JUL/22
A29: Veracruz | B29: 44608 | C29: 44642 | F29: 44655 | G29: 44705 | H29: 22-527 | I29: C-316 | J29: SONORA | K29: Confirmado | L29: 92831295 | M29: 44712 | N29: =+C29+60 -> 44702 | P29: INFO ACTUALIZADA AL 03/JUN/22
A30: Veracruz | B30: 44616 | C30: 44671 | F30: 44697 | G30: 44739 | H30: 22-528 | I30: C-317 | J30: 3B | K30: Entregado | L30: 92845157 | M30: 44748 | N30: =+C30+60 -> 44731 | O30: 44761 | P30: INFO ACTUALIZADA AL 19/JUL/22
B31: 44624 | F31: 44741 | G31: 44764 | H31: 22-529 | I31: C-318 | J31: 3B/LA COMER | K31: Cancelado | N31: =+C31+60 -> 60 | P31: INFO ACTUALIZADA AL 27/MAY/22
B32: 44624 | F32: 44712 | G32: 44732 | H32: 22-530 | I32: C-319 | J32: 3B/LA COMER | K32: Cancelado | N32: =+C32+60 -> 60 | P32: INFO ACTUALIZADA AL 27/MAY/22
A33: Veracruz | B33: 44624 | C33: 44694 | F33: 44701 | G33: 44757 | H33: 22-531 | I33: C-320 | J33: SONORA/ANILU | K33: Entregado | L33: 92855909 | M33: 44761 | N33: =+C33+60 -> 44754 | O33: 44785 | P33: INFO ACTUALIZADA AL 15/JUL/22
B34: 44631 | F34: 44700 | G34: 44720 | H34: 22-532 | I34: C-321 | J34: 3B | K34: Cancelado | N34: =+C34+60 -> 60 | P34: INFO ACTUALIZADA AL 05/JUL/22
A35: Veracruz | B35: 44721 | C35: 44741 | F35: 44751 | G35: 44775 | H35: 22-533 | I35: C-322 | J35: SONORA/CUN | K35: Entregado | L35: 92880484 | M35: 44783 | N35: =+C35+60 -> 44801 | O35: 44802 | P35: INFO ACTUALIZADA AL 29/AGO/22
A36: Veracruz | B36: 44739 | C36: 44763 | F36: 44771 | G36: 44807 | H36: 22-534 | I36: C-323 | J36: SONORA | K36: Entregado | L36: 92892125 | M36: 44813 | N36: =+C36+60 -> 44823 | O36: 44823 | P36: INFO ACTUALIZADA AL 19/SEPT/22
A37: Progreso | B37: 44750 | H37: 22-535 | I37: C-324 | J37: ABASTOS L. | K37: Cancelado | P37: INFO ACTUALIZADA AL 15/JUL/22
A38: Veracruz | B38: 44768 | C38: 44809 | F38: 44818 | G38: 44835 | H38: 22-536 | I38: C-325 | J38: SONORA/ANILU | K38: Confirmado | L38: 92914997 | M38: 44840 | N38: =+C38+60 -> 44869 | O38: 44869 | P38: INFO ACTUALIZADA AL 06/OCT/22
A39: Altamira | B39: 44770 | C39: 44826 | D39: 37649.07 | F39: 44830 | G39: 44857 | H39: 22-537 | I39: C-326 | J39: VULPES | K39: Entregado | L39: 92923642 | M39: 44863 | N39: =+C39+60 -> 44886 | O39: 44887 | P39: INFO ACTUALIZADA AL 22/NOV/22
A40: Veracruz | B40: 44778 | C40: 44829 | D40: 32065.2 | F40: 44830 | G40: 44857 | H40: 22-538 | I40: C-327 | J40: SONORA/ANILU | K40: Entregado | L40: 92925081 | M40: 44867 | N40: =+C40+60 -> 44889 | O40: 44890 | P40: INFO ACTUALIZADA AL 25/NOV/22
A41: Veracruz | B41: 44805 | C41: 44848 | D41: 35675.4 | F41: 44856 | G41: 44890 | H41: 22-539 | I41: C-328 | J41: SONORA | K41: Confirmado | L41: 92935141 | M41: 44901 | N41: =+C41+60 -> 44908 | O41: 44909 | P41: INFO ACTUALIZADA AL 25/NOV/22
A42: Veracruz | B42: 44805 | C42: 44861 | D42: 36052.44 | F42: 44868 | G42: 44893 | H42: 22-540 | I42: C-329 | J42: SONORA/ANILU | K42: Entregado | L42: 92941211 | M42: 44905 | N42: =+C42+60 -> 44921 | O42: 44921 | P42: INFO ACTUALIZADA AL 26/DIC/22
A43: Veracruz | B43: 44894 | C43: 44915 | D43: 35327.85 | F43: 44925 | G43: 44941 | H43: 22-541 | I43: C-330 | J43: SONORA/ANILU/MUESTRAS | K43: Entregado | L43: 92968049 | M43: 44946 | N43: =+C43+60 -> 44975 | O43: 44974 | P43: PAGADO
...

Sheet Buscador

Sheet Aviko Control
A1: AVIKO CONTRO DE CUENTAS X PAGAR
A2: # contenedor | B2: fecha pedido | C2: Fecha Proforma | D2: fecha fact -2 | E2: ETD | F2: ETA puerto | G2: valor | H2: Saldo con ETD | I2: saldo con proforma | J2: saldo vs fact | K2: saldo vs Eta | L2: Vencimientos | M2: FECHA DE PAGO
A3: C-346 | B3: =+Contenedores!B58 -> 45217 | C3: 45250 | D3: =+Contenedores!C59 -> 45250 | F3: =+Contenedores!G59 -> 45275 | G3: 0 | I3: =+G3 -> 0 | J3: =+G3 -> 0 | K3: =+G3 -> 0
A4: C-347 | B4: =+Contenedores!B59 -> 45226 | D4: =+Contenedores!C60 -> 45250 | F4: =+Contenedores!G60 -> 45275 | G4: 0 | I4: =+I3+G4 -> 0 | J4: =+J3+G4 -> 0 | K4: =+K3+G4 -> 0
A5: C-348 | B5: =+Contenedores!B60 -> 45239 | C5: 45274 | D5: =+Contenedores!C61 -> 45276 | E5: =+Contenedores!F61 -> 45282 | F5: =+Contenedores!G61 -> 45314 | H5: =+G5 -> 0 | I5: =+I4+G5 -> 0 | J5: =+J4+G5 -> 0 | K5: =+K4+G5 -> 0
A6: C-349 | B6: =+Contenedores!B61 -> 45257 | D6: =+Contenedores!C62 -> 45293 | E6: =+Contenedores!F62 -> 45297 | F6: =+Contenedores!G62 -> 45318 | G6: 0 | H6: =+G6 -> 0 | I6: =+G6 -> 0 | J6: =+J5+G6 -> 0
A7: C-350 | B7: =+Contenedores!B62 -> 45261 | D7: =+Contenedores!C63 -> 45282 | E7: =+Contenedores!F63 -> 45289 | F7: =+Contenedores!G63 -> 45347 | G7: 0 | J7: =+J6+G7 -> 0
A8: C-351 | B8: =+Contenedores!B63 -> 45267 | C8: 45308 | E8: =+Contenedores!F64 -> 45314 | F8: =+Contenedores!G64 -> 45344 | G8: 0 | H8: =+H6+G8 -> 0 | I8: =+I6+G8 -> 0
A9: C-352 | B9: =+Contenedores!B64 -> 45287 | C9: 45308 | E9: =+Contenedores!F65 -> 45314 | F9: =+Contenedores!G65 -> 45344 | G9: 0 | H9: =+H8+G9 -> 0 | I9: =+I8+G9 -> 0
A10: C-353 | B10: =+Contenedores!B65 -> 45295 | C10: 45320 | E10: =+Contenedores!F66 -> 45324 | F10: =+Contenedores!G66 -> 45346 | G10: 0 | H10: =+H9+G10 -> 0 | I10: =+I9+G10 -> 0 | L10: =+Contenedores!N66 -> 45380
A11: C-354 | B11: =+Contenedores!B66 -> 45300 | C11: 45320 | E11: =+Contenedores!F67 -> 45324 | F11: =+Contenedores!G67 -> 45346 | G11: 0 | H11: =+H10+G11 -> 0 | I11: =+I10+G11 -> 0 | L11: =+Contenedores!N67 -> 45383 | M11: 45373
A12: C-355 | B12: =+Contenedores!B67 -> 45300 | C12: 45322 | E12: =+Contenedores!F68 -> 45327 | F12: 45356 | G12: 0 | H12: =+H11+G12 -> 0 | I12: =+I11+G12 -> 0 | L12: =+Contenedores!N68 -> 45381 | M12: 45365
A13: C-356 | B13: =+Contenedores!B68 -> 45307 | C13: =+Contenedores!C69 -> 45344 | E13: =+Contenedores!F69 -> 45350 | F13: =+Contenedores!G69 -> 45384 | H13: =+H12+G13 -> 0 | L13: =+Contenedores!N69 -> 45404 | M13: 45387
A14: C-357 | B14: =+Contenedores!B69 -> 45308 | C14: =+Contenedores!C70 -> 45367 | E14: =+Contenedores!F70 -> 45373 | F14: =+Contenedores!G70 -> 45398 | G14: 0 | H14: =+H13+G14 -> 0 | L14: =+Contenedores!N70 -> 45427 | M14: 45414
A15: C-358 | B15: =+Contenedores!B70 -> 45322 | C15: =+Contenedores!C71 -> 45357 | E15: =+Contenedores!F71 -> 45360 | F15: =+Contenedores!G71 -> 45384 | H15: =+H14+G15 -> 0 | L15: =+Contenedores!N71 -> 45417 | M15: 45392
A16: C-359 | B16: =+Contenedores!B71 -> 45336 | C16: =+Contenedores!C72 -> 45365 | E16: =+Contenedores!F72 -> 45373 | F16: =+Contenedores!G72 -> 45398 | H16: =+H14+G16 -> 0 | L16: =+Contenedores!N72 -> 45425 | M16: 45397
A17: C-360 | B17: =+Contenedores!B72 -> 45337 | C17: =+Contenedores!C73 -> 45365 | E17: =+Contenedores!F73 -> 45373 | F17: =+Contenedores!G73 -> 45398 | G17: 0 | H17: =+H16+G17 -> 0 | L17: =+Contenedores!N73 -> 45425 | M17: 45412
A18: C-361 | B18: =+Contenedores!B73 -> 45337 | C18: =+Contenedores!C74 -> 45365 | E18: =+Contenedores!F74 -> 45373 | F18: =+Contenedores!G74 -> 45398 | H18: =+H17+G18 -> 0 | L18: =+Contenedores!N74 -> 45425 | M18: 45414
A19: C-362 | B19: =+Contenedores!B75 -> 45362 | C19: =+Contenedores!C75 -> 45379 | E19: =+Contenedores!F75 -> 45385 | F19: =+Contenedores!G75 -> 45415 | G19: 0 | H19: =+H18+G19 -> 0 | L19: =+Contenedores!N75 -> 45439 | M19: 45433
A20: =+Contenedores!I76 -> C-363 | B20: =+Contenedores!B76 -> 45373 | C20: 45411 | E20: 45415 | F20: 45436 | G20: 0 | H20: =+H19+G20 -> 0 | L20: 45471 | M20: 45471
A21: =+Contenedores!I77 -> C-364 | B21: =+Contenedores!B77 -> 45365 | C21: =+Contenedores!C77 -> 45391 | E21: =+Contenedores!F77 -> 45397 | F21: =+Contenedores!G77 -> 45426 | H21: =+H20+G21 -> 0 | L21: =+Contenedores!N77 -> 45451 | M21: 45441
A22: =+Contenedores!I78 -> C-365 | B22: =+Contenedores!B78 -> 45365 | C22: =+Contenedores!C78 -> 45391 | E22: =+Contenedores!F78 -> 45397 | F22: =+Contenedores!G78 -> 45426 | H22: =+H21+G22 -> 0 | L22: =+Contenedores!N78 -> 45451 | M22: 45441
A23: =+Contenedores!I79 -> C-366 | B23: =+Contenedores!B79 -> 45373 | C23: =+Contenedores!C79 -> 45441 | E23: 45422 | F23: =+Contenedores!G79 -> 45486 | G23: 0 | H23: =+H22+G23 -> 0 | L23: 45501 | M23: 45502
A24: =+Contenedores!I80 -> C-367 | B24: =+Contenedores!B80 -> 45385 | C24: =+Contenedores!C80 -> 45418 | E24: 45422 | F24: 45446 | G24: 0 | H24: =+H23+G24 -> 0 | L24: 45478 | M24: 45478
A25: =+Contenedores!I81 -> C-368 | B25: =+Contenedores!B81 -> 45394 | C25: 45420 | E25: 45422 | F25: 45444 | G25: 0 | H25: =+H24+G25 -> 0 | L25: 45480 | M25: 45481
A26: =+Contenedores!I82 -> C-369 | B26: =+Contenedores!B82 -> 45394 | C26: 45417 | E26: 45423 | F26: 45453 | G26: 0 | H26: =+H25+G26 -> 0 | L26: 45478 | M26: 45478
A27: =+Contenedores!I83 -> C-370 | B27: =+Contenedores!B83 -> 45401 | C27: 45429 | E27: 45437 | F27: 45457 | G27: 0 | H27: =+H26+G27 -> 0 | L27: 45490 | M27: 45489
A28: =+Contenedores!I84 -> C-371 | B28: =+Contenedores!B84 -> 45405 | C28: 45429 | E28: 45437 | F28: 45457 | G28: 0 | H28: =+H27+G28 -> 0 | L28: 45489 | M28: 45489
A29: =+Contenedores!I85 -> C-372 | B29: 45414 | C29: 45430 | E29: 45437 | F29: 45457 | G29: 0 | H29: =+H28+G29 -> 0 | L29: 45490 | M29: 45489
A30: =+Contenedores!I86 -> C-373 | B30: 45428 | C30: 45450 | E30: 45457 | F30: 45499 | G30: 0 | H30: =+H29+G30 -> 0 | L30: 45510 | M30: 45531
A31: =+Contenedores!I87 -> C-374 | B31: 45428 | C31: 45450 | E31: 45457 | F31: 45481 | G31: 0 | H31: =+H30+G31 -> 0 | L31: 45510 | M31: 45510
A32: =+Contenedores!I88 -> C-375 | B32: 45435 | C32: 45449 | E32: 45457 | F32: 45481 | G32: 0 | H32: =+H31+G32 -> 0 | L32: 45509 | M32: 45511
A33: c-376 | B33: 45448 | C33: 45474 | E33: 45478 | F33: 45499 | G33: 0 | H33: =+H32+G33 -> 0 | L33: 45534 | M33: 45531
A34: C-377 | B34: 45479 | C34: 45497 | E34: 45502 | F34: 45522 | G34: 0 | H34: =+H33+G34 -> 0 | L34: 45557 | M34: 45559
A35: C-378 | B35: 45527 | C35: 45540 | E35: 45543 | F35: 45563 | G35: 0 | H35: =+H34+G35 -> 0 | L35: 45599 | M35: 45600
A36: C-379 | B36: 45539 | C36: 45560 | E36: 45566 | F36: 45585 | G36: 0 | H36: =+H35+G36 -> 0 | L36: 45620 | M36: 45621
A37: C-380 | B37: 45544 | C37: 45560 | E37: 45567 | F37: 45593 | G37: 0 | H37: =+H36+G37 -> 0 | L37: 45620 | M37: 45621
A38: C-381 | B38: 45565 | C38: 45581 | E38: 45587 | F38: 45607 | H38: =+H37+G38 -> 0 | L38: 45641
A39: C-382 | B39: 45569 | C39: 45587 | E39: 45592 | F39: 45615 | H39: =+H38+G39 -> 0 | L39: 45647
A40: C-383 | B40: 45581 | C40: 45595 | E40: 45599 | F40: 45620 | H40: =+H39+G40 -> 0 | L40: 45655
...

Sheet Wernisng Control
A1: AVIKO CONTRO DE CUENTAS X PAGAR
A2: # contenedor | B2: fecha pedido | C2: fecha fact | D2: ETD | E2: ETA puerto | F2: valor | G2: Saldo con ETD | H2: saldo con proforma | I2: saldo vs fact | J2: saldo vs Eta | K2: Vencimientos | L2: FECHA DE PAGO
A3: =+Contenedores!I217 -> C-78 | B3: =+Contenedores!B217 -> 45625 | C3: =+Contenedores!C217 -> 45636 | D3: =+Contenedores!F217 -> 45638 | E3: =+Contenedores!G215 -> 45653 | G3: =+F3 -> 0 | K3: =+Contenedores!N217 -> 45681
A4: =+Contenedores!I218 -> C-79 | B4: =+Contenedores!B218 -> 45632 | C4: =+Contenedores!C218 -> 45639 | D4: =+Contenedores!F218 -> 45642 | E4: =+Contenedores!G216 -> 45655 | G4: =+G3+F4 -> 0 | K4: =+Contenedores!N218 -> 45684
A5: =+Contenedores!I219 -> C-80 | B5: =+Contenedores!B219 -> 45639 | C5: =+Contenedores!C219 -> 45665 | D5: =+Contenedores!F219 -> 45303 | E5: =+Contenedores!G217 -> 45701 | G5: =+G4+F5 -> 0 | K5: =+Contenedores!N219 -> 45710
A6: =+Contenedores!I220 -> C-81 | B6: =+Contenedores!B220 -> 45644 | C6: =+Contenedores!C220 -> 45671 | D6: =+Contenedores!F220 -> 45673 | E6: =+Contenedores!G218 -> 45664 | G6: =+G5+F6 -> 0 | K6: =+Contenedores!N220 -> 45716
A7: =+Contenedores!I221 -> C-82 | B7: =+Contenedores!B221 -> 45644 | C7: =+Contenedores!C221 -> 45665 | D7: =+Contenedores!F221 -> 45669 | E7: =+Contenedores!G219 -> 45688 | G7: =+G6+F7 -> 0 | K7: =+Contenedores!N221 -> 45710
A8: =+Contenedores!I222 -> C-83 | B8: =+Contenedores!B222 -> 45666 | C8: =+Contenedores!C222 -> 45679 | D8: =+Contenedores!F222 -> 45683 | E8: =+Contenedores!G220 -> 45703 | G8: =+G7+F8 -> 0 | K8: =+Contenedores!N222 -> 45724
A9: =+Contenedores!I223 -> C-84 | B9: =+Contenedores!B223 -> 45667 | C9: =+Contenedores!C223 -> 45693 | D9: =+Contenedores!F223 -> 45690 | E9: =+Contenedores!G221 -> 45688 | G9: =+G8+F9 -> 0 | K9: =+Contenedores!N223 -> 45738
A10: =+Contenedores!I224 -> C-85 | B10: =+Contenedores!B224 -> 45672 | C10: =+Contenedores!C224 -> 45698 | D10: =+Contenedores!F224 -> 45725 | E10: =+Contenedores!G222 -> 45719 | G10: =+G9+F10 -> 0
A11: =+Contenedores!I225 -> C-86 | B11: =+Contenedores!B225 -> 45678 | C11: =+Contenedores!C225 -> 45721 | D11: =+Contenedores!F225 -> 45725 | E11: =+Contenedores!G223 -> 45720 | F11: 0 | G11: =+G10+F11 -> 0
A12: =+Contenedores!I226 -> C-87 | B12: =+Contenedores!B226 -> 45695 | C12: =+Contenedores!C226 -> 45702 | D12: =+Contenedores!F226 -> 45706 | E12: =+Contenedores!G224 -> 45744 | G12: =+G11+F12 -> 0
A13: =+Contenedores!I227 -> C-88 | B13: =+Contenedores!B227 -> 45695 | C13: =+Contenedores!C227 -> 45716 | D13: =+Contenedores!F227 -> 45719 | E13: =+Contenedores!G225 -> 45743 | F13: 0 | G13: =+G12+F13 -> 0
A14: =+Contenedores!I228 -> C-89 | B14: =+Contenedores!B228 -> 45695 | C14: =+Contenedores!C228 -> 45702 | D14: =+Contenedores!F228 -> 45706 | E14: =+Contenedores!G226 -> 45743 | G14: =+G13+F14 -> 0
A15: =+Contenedores!I229 -> C-90 | B15: =+Contenedores!B229 -> 45695 | C15: =+Contenedores!C229 -> 45742 | D15: =+Contenedores!F229 -> 45745 | E15: =+Contenedores!G227 -> 45751 | G15: =+G14+F15 -> 0
A16: =+Contenedores!I230 -> C-91 | B16: =+Contenedores!B230 -> 45768 | C16: =+Contenedores!C230 -> 45772 | D16: =+Contenedores!F230 -> 0 | E16: =+Contenedores!G228 -> 45743 | G16: =+G15+F16 -> 0
A17: =+Contenedores!I231 -> C-92 | B17: =+Contenedores!B231 -> 45716 | C17: =+Contenedores!C231 -> 45723 | D17: =+Contenedores!F231 -> 45726 | E17: =+Contenedores!G229 -> 45764 | G17: =+G16+F17 -> 0
A18: =+Contenedores!I232 -> C-93 | B18: =+Contenedores!B232 -> 45740 | C18: =+Contenedores!C232 -> 45747 | D18: =+Contenedores!F232 -> 45754 | E18: =+Contenedores!G232 -> 45786 | G18: =+G17+F18 -> 0
A19: =+Contenedores!I233 -> C-94 | B19: =+Contenedores!B233 -> 45791 | C19: =+Contenedores!C233 -> 45813 | D19: =+Contenedores!F233 -> 45815 | E19: =+Contenedores!G233 -> 45838 | G19: =+G18+F19 -> 0
A20: =+Contenedores!I234 -> C-95 | B20: =+Contenedores!B234 -> 45791 | C20: =+Contenedores!C234 -> 45807 | D20: =+Contenedores!F234 -> 45808 | E20: =+Contenedores!G234 -> 45827 | G20: =+G19+F20 -> 0
A21: =+Contenedores!I235 -> C-96 | B21: =+Contenedores!B235 -> 45840 | C21: =+Contenedores!C235 -> 45860 | D21: =+Contenedores!F235 -> 0 | E21: =+Contenedores!G235 -> 45877
A22: =+Contenedores!I236 -> C-97 | B22: =+Contenedores!B236 -> 45840 | C22: =+Contenedores!C236 -> 45856 | D22: =+Contenedores!F236 -> 0 | E22: =+Contenedores!G236 -> 45883
A23: =+Contenedores!I237 -> C-98 | B23: =+Contenedores!B237 -> 45876 | C23: =+Contenedores!C237 -> 45897 | D23: =+Contenedores!F237 -> 0 | E23: =+Contenedores!G237 -> 45918
A24: =+Contenedores!I238 -> C-99 | B24: =+Contenedores!B238 -> 45876 | C24: =+Contenedores!C238 -> 45897 | D24: =+Contenedores!F238 -> 0 | E24: =+Contenedores!G238 -> 45918
A25: =+Contenedores!I239 -> C-100 | B25: =+Contenedores!B239 -> 45908 | C25: =+Contenedores!C239 -> 45917 | D25: =+Contenedores!F239 -> 0 | E25: =+Contenedores!G239 -> 45941 | F25: =+Contenedores!D239 -> 28373.8 | G25: =+G24+F25 -> 28373.8
A26: =+Contenedores!I240 -> C-101 | B26: =+Contenedores!B240 -> 45939 | C26: =+Contenedores!C240 -> 45950 | D26: =+Contenedores!F240 -> 45952 | E26: =+Contenedores!G240 -> 45976 | F26: =+Contenedores!D240 -> 29447.9 | G26: =+G25+F26 -> 57821.7
A27: =+Contenedores!I241 -> C-102 | B27: =+Contenedores!B241 -> 45947 | C27: =+Contenedores!C241 -> 45960 | D27: =+Contenedores!F241 -> 45965 | E27: =+Contenedores!G241 -> 46015 | F27: =+Contenedores!D241 -> 25565.4 | G27: =+G26+F27 -> 83387.1
A28: =+Contenedores!I242 -> C-103 | B28: =+Contenedores!B242 -> 45960 | C28: =+Contenedores!C242 -> 45973 | D28: =+Contenedores!F242 -> 45976 | E28: =+Contenedores!G242 -> 45997 | F28: =+Contenedores!D242 -> 28212.4 | G28: =+G27+F28 -> 111599.5
A29: =+Contenedores!I243 -> C-104 | B29: =+Contenedores!B243 -> 45961 | C29: =+Contenedores!C243 -> 45978 | D29: =+Contenedores!F243 -> 45979 | E29: =+Contenedores!G243 -> 46015 | F29: =+Contenedores!D243 -> 27873 | G29: =+G28+F29 -> 139472.5
A30: =+Contenedores!I244 -> C-105 | B30: =+Contenedores!B244 -> 45971 | C30: =+Contenedores!C244 -> 45980 | D30: =+Contenedores!F244 -> 0 | E30: =+Contenedores!G244 -> 45997 | F30: =+Contenedores!D244 -> 26210 | G30: =+G29+F30 -> 165682.5
F34: =SUM(F3:F33) -> 165682.5
D36: LNEA DE CREDITO | F36: 400000
F37: =+F36-F34 -> 234317.5

Sheet ETA REAL
A1: AVIKO
A3: C/P.O | C3: Puerto | D3: Fech pedido | E3: Fech Fact | F3: PROFORMA/ CONFIRMACION | G3: DIAS P/CONFIRMACION | H3: ETD SOLICITADO | I3: ETA SOLICITADO | J3: ETD FACTURADO | K3: ETA FACTURADO | L3: R. ETA SOL. Y ETA FACT | M3: ETD REAL | N3: ETA REAL | O3: RETRASOS | P3: TOTAL RETRASOS | Q3: Clte | R3: ENTREGA | S3: Factura | T3: Importe | U3: Vencim | V3: Pago | W3: BL | X3: BUQUE
A4: 307/ 21-518 | C4: VERACRUZ | D4: 44512 | E4: 44537 | F4: 44530 | G4: =_xlfn.DAYS(D4,F4) -> -18 | H4: 44544 | I4: 44564 | J4: 44545 | K4: 44565 | L4: =_xlfn.DAYS(I4,K4) -> -1 | M4: 44550 | N4: 44571 | O4: =_xlfn.DAYS(K4,N4) -> -6 | P4: =+L4+O4 -> -7 | Q4: 3TD | R4: E | S4: 92782952 | T4: 19696.44 | U4: 44597 | V4: 44600
A5: 300/ 21-511 | C5: PROGRESO | D5: 44477 | E5: 44532 | F5: 44519 | G5: =_xlfn.DAYS(D5,F5) -> -42 | H5: 44514 | I5: 44535 | J5: 44538 | K5: 44565 | L5: =_xlfn.DAYS(I5,K5) -> -30 | M5: 44540 | N5: 44572 | O5: =_xlfn.DAYS(K5,N5) -> -7 | P5: =+L5+O5 -> -37 | Q5: ABASTOS | R5: E | S5: 92781106 | T5: 24027.48 | U5: 44592 | V5: 44592
A6: 299/ 21-510 | C6: VERACRUZ | D6: 44434 | E6: 44533 | F6: 44516 | G6: =_xlfn.DAYS(D6,F6) -> -82 | H6: 44513 | I6: 44533 | J6: 44540 | K6: 44559 | L6: =_xlfn.DAYS(I6,K6) -> -26 | M6: 44542 | N6: 44573 | O6: =_xlfn.DAYS(K6,N6) -> -14 | P6: =+L6+O6 -> -40 | Q6: 3B | R6: E | S6: 92781508 | T6: 19812.48 | U6: 44593 | V6: 44229
A7: 302/ 21-513 | C7: VERACRUZ | D7: 44434 | E7: 44533 | F7: 44516 | G7: =_xlfn.DAYS(D7,F7) -> -82 | H7: 44523 | I7: 44543 | J7: 44540 | K7: 44559 | L7: =_xlfn.DAYS(I7,K7) -> -16 | M7: 44542 | N7: 44573 | O7: =_xlfn.DAYS(K7,N7) -> -14 | P7: =+L7+O7 -> -30 | Q7: 3TD | R7: E | S7: 92781453 | T7: 19807.2 | U7: 44593 | V7: 44230
A8: 303/ 21-514 | C8: PROGRESO | D8: 44434 | E8: 44539 | F8: 44539 | G8: =_xlfn.DAYS(D8,F8) -> -105 | H8: 44542 | I8: 44563 | J8: 44545 | K8: 44572 | L8: =_xlfn.DAYS(I8,K8) -> -9 | M8: 44550 | N8: 44591 | O8: =_xlfn.DAYS(K8,N8) -> -19 | P8: =+L8+O8 -> -28 | Q8: ABASTOS | R8: E | S8: 92784317 | T8: 24339.12 | U8: 44234 | V8: 44236
A9: 304/ 21-515 | C9: VERACRUZ | D9: 44434 | E9: 44565 | F9: 44536 | G9: =_xlfn.DAYS(D9,F9) -> -102 | H9: 44548 | I9: 44568 | J9: 44208 | K9: 44592 | L9: =_xlfn.DAYS(I9,K9) -> -24 | M9: 44572 | N9: 44594 | O9: =_xlfn.DAYS(K9,N9) -> -2 | P9: =+L9+O9 -> -26 | Q9: 3B | R9: E | S9: 92793939 | T9: 19734.48 | U9: 44260 | V9: 44627
A10: 308/ 21-519 | C10: VERACRUZ | D10: 44512 | E10: 44206 | F10: 44543 | G10: =_xlfn.DAYS(D10,F10) -> -31 | H10: 44537 | I10: 44557 | J10: 44587 | K10: 44610 | L10: =_xlfn.DAYS(I10,K10) -> -53 | M10: 44600 | N10: 44622 | O10: =_xlfn.DAYS(K10,N10) -> -12 | P10: =+L10+O10 -> -65 | Q10: 3B | R10: E | S10: 92796168 | T10: 21306.6 | U10: 44266 | V10: 44634
A11: 309/ 21-520 | C11: VERACRUZ | D11: 44532 | E11: 44209 | F11: 44573 | G11: =_xlfn.DAYS(D11,F11) -> -41 | H11: 44562 | I11: 44593 | J11: 44580 | K11: 44600 | L11: =_xlfn.DAYS(I11,K11) -> -7 | M11: 44600 | N11: 44622 | O11: =_xlfn.DAYS(K11,N11) -> -22 | P11: =+L11+O11 -> -29 | Q11: 3B | R11: E | S11: 92798101 | T11: 26257.2 | U11: 44634 | V11: 44638
A12: 310/ 21-521 | C12: VERACRUZ | D12: 44532 | E12: 44592 | F12: 44587 | G12: =_xlfn.DAYS(D12,F12) -> -55 | H12: 44610 | I12: 44630 | J12: 44611 | K12: 44635 | L12: =_xlfn.DAYS(I12,K12) -> -5 | M12: 44618 | N12: 44654 | O12: =_xlfn.DAYS(K12,N12) -> -19 | P12: =+L12+O12 -> -24 | Q12: 3B | R12: E | S12: 92805982 | T12: 26126.4 | U12: 44635
A13: 311/ 21-522 | C13: VERACRUZ | D13: 44538 | E13: 44208 | F13: 44560 | G13: =_xlfn.DAYS(D13,F13) -> -22 | H13: 44566 | I13: 44586 | J13: 44587 | K13: 44608 | L13: =_xlfn.DAYS(I13,K13) -> -22 | M13: 44600 | N13: 44622 | O13: =_xlfn.DAYS(K13,N13) -> -14 | P13: =+L13+O13 -> -36 | Q13: LA COMER | R13: E | S13: 92797446 | T13: 23213.64 | U13: 44636 | V13: 44635
A14: 312/ 22-523 | C14: VERACRUZ | D14: 44581 | E14: 44643 | F14: 44602 | G14: =_xlfn.DAYS(D14,F14) -> -21 | H14: 44607 | I14: 44627 | J14: 44644 | K14: 44661 | L14: =_xlfn.DAYS(I14,K14) -> -34 | M14: 44667 | N14: 44692 | O14: =_xlfn.DAYS(K14,N14) -> -31 | P14: =+L14+O14 -> -65 | Q14: 3TD/LEON | R14: E | S14: 92831908 | T14: 24356.16 | U14: =+E14+60 -> 44703 | W14: 913917834 | X14: MSC MARINA
A15: 313/ 22-524 | C15: VERACRUZ | D15: 44602 | E15: 44623 | F15: 44613 | G15: =_xlfn.DAYS(D15,F15) -> -11 | H15: 44619 | I15: 44639 | J15: 44630 | K15: 44644 | L15: =_xlfn.DAYS(I15,K15) -> -5 | M15: 44628 | N15: 44648 | O15: =_xlfn.DAYS(K15,N15) -> -4 | P15: =+L15+O15 -> -9 | Q15: 3B | R15: E | S15: 92821407 | T15: 25999.2 | U15: =+E15+60 -> 44683 | V15: 44685
A16: 314/ 22-525 | C16: VERACRUZ | D16: 44602 | E16: 44670 | F16: 44614 | G16: =_xlfn.DAYS(D16,F16) -> -12 | H16: 44634 | I16: 44654 | J16: 44676 | K16: 44694 | L16: =_xlfn.DAYS(I16,K16) -> -40 | M16: 44697 | N16: 44737 | O16: =_xlfn.DAYS(K16,N16) -> -43 | P16: =+L16+O16 -> -83 | Q16: 3B | R16: E | S16: 92844225 | T16: 26294.4 | U16: =+E16+60 -> 44730 | W16: 914128937 | X16: MAERSK KLEVEN
A17: 316/ 22-527 | C17: VERACRUZ | D17: 44608 | E17: 44642 | F17: 44630 | G17: =_xlfn.DAYS(D17,F17) -> -22 | H17: 44641 | I17: 44661 | J17: 44649 | K17: 44667 | L17: =_xlfn.DAYS(I17,K17) -> -6 | M17: 44661 | N17: 44704 | O17: =_xlfn.DAYS(K17,N17) -> -37 | P17: =+L17+O17 -> -43 | Q17: SONORA | R17: E | S17: 92831295 | T17: 24775.2 | U17: =+E17+60 -> 44702 | W17: 914033517 | X17: SEALAND ILLINOIS
A18: 317/ 22-528 | C18: VERACRUZ | D18: 44616 | E18: 44671 | F18: 44656 | G18: =_xlfn.DAYS(D18,F18) -> -40 | H18: 44672 | I18: 44692 | J18: 44677 | K18: 44694 | L18: =_xlfn.DAYS(I18,K18) -> -2 | M18: 44697 | N18: 44737 | O18: =_xlfn.DAYS(K18,N18) -> -43 | P18: =+L18+O18 -> -45 | Q18: 3B | R18: E | S18: 92845157 | T18: 32938.2 | U18: =+E18+60 -> 44731 | W18: 914170719 | X18: MAERSK KLEVEN
A19: 318/22-529 | C19: VERACRUZ | D19: 44624 | F19: 44687 | G19: =_xlfn.DAYS(D19,F19) -> -63 | H19: 44696 | I19: 44716 | J19: 44741 | K19: 44764 | L19: =_xlfn.DAYS(I19,K19) -> -48 | O19: =_xlfn.DAYS(K19,N19) -> 44764 | P19: =+L19+O19 -> 44716 | Q19: 3B/LA COMER | R19: P
A20: 320/22-531 | C20: VERACRUZ | D20: 44624 | E20: 44694 | F20: 44687 | H20: 44683 | I20: 44703 | J20: 44700 | K20: 44724 | L20: =_xlfn.DAYS(I20,K20) -> -21 | M20: 44701 | N20: 44757 | O20: =_xlfn.DAYS(K20,N20) -> -33 | P20: =+L20+O20 -> -54 | Q20: SONORA/ANILU | R20: E | S20: 92855909 | T20: 31602.84 | U20: 44754 | W20: 218051476 | X20: MSC ANCHORAGE
A21: 322/22-533 | C21: VERACRUZ | D21: 44721 | E21: 44741 | F21: 44734 | H21: 44768 | I21: 44788 | J21: 44747 | K21: 44800 | L21: =_xlfn.DAYS(I21,K21) -> -12 | M21: 44751 | N21: 44775 | O21: =_xlfn.DAYS(K21,N21) -> 25 | P21: =+L21+O21 -> 13 | Q21: SONORA/CUN | R21: E | S21: 92880484 | T21: 30766.76 | U21: 44801 | W21: 219246056 | X21: MAERSK GATESHEAD
A22: 323/22-534 | C22: VERACRUZ | D22: 44739 | E22: 44763 | F22: 44753 | H22: 44768 | I22: 44788 | J22: 44771 | K22: 44831 | L22: =_xlfn.DAYS(I22,K22) -> -43 | M22: 44770 | N22: 44812 | O22: =_xlfn.DAYS(K22,N22) -> 19 | P22: =+L22+O22 -> -24 | Q22: SONORA | R22: E | S22: 92892125 | T22: 32500.8 | U22: 44823 | W22: 914452463 | X22: NORTHERN MAJESTIC
A23: 324/22-535 | C23: PROGRESO | D23: 44750 | F23: 44757 | Q23: ABASTOS | R23: P
A24: 325/22-536 | C24: VERACRUZ
D29: =_xlfn.DAYS(N16,D16) -> 135 | E29: dias del pedido a eta real
D30: =_xlfn.DAYS(N17,D17) -> 96 | E30: dias del pedido a eta real
D31: =_xlfn.DAYS(N18,D18) -> 121 | E31: dias del pedido a eta real

Sheet CUENTAS X PAGAR AVIKO
A1: OXDA SA DE CV
A2: CUENTAS POR PAGAR AVIKO EUROS
A4: AVIKO | Y4: 2020 | Z4: 2020 | AA4: 2020 | AB4: 2020 | AC4: 2020 | AD4: 2020 | AE4: 2020 | AF4: 2020 | AG4: 2020 | AH4: 2020 | AI4: 2020 | AJ4: 2020 | AK4: 2021 | AL4: 2021 | AM4: 2021 | AN4: 2021 | AO4: 2021 | AP4: 2021 | AQ4: 2021 | AR4: 2021 | AS4: 2021 | AT4: 2021 | AU4: 2021 | AV4: 2021 | AW4: 2022 | AX4: 2022 | AY4: 2022 | BA4: FIX (PEDIMENTO) | BB4: FACTOR MON.FACT | BC4: T.C EURO
A5: FECHA FACTURA | B5: ETD | C5: ETA | D5: BL | E5: ETA RAL | F5: No. PROFORMA | G5: CONTENEDOR | H5: No. FACTURA | I5: DESTINO | J5: IMPORTE | K5: CLIENTE | L5: FECHA DE VENCIMIENTO FACTURA | M5: ENERO | N5: FEBRERO | O5: MARZO | P5: ABRIL | Q5: MAYO | R5: JUNIO | S5: JULIO | T5: AGOSTO | U5: SEPTIEMBRE | V5: OCTUBRE | W5: NOVIEMBRE | X5: DICIEMBRE | Y5: ENERO | Z5: FEBRERO | AA5: MARZO | AB5: ABRIL | AC5: MAYO | AD5: JUNIO | AE5: JULIO | AF5: AGOSTO | AG5: SEP | AH5: OCT | AI5: NOV | AJ5: DIC | AK5: ENE | AL5: FEB | AM5: MAR | AN5: ABR | AO5: MAY | AP5: JUN | AQ5: JUL | AR5: AGO | AS5: SEP | AT5: OCT | AU5: NOV | AV5: DIC | AW5: ENE | AX5: FEB | AY5: MAR | AZ5: TOTAL | BA5: Dlls | BD5: IMPORTE TOTAL | BE5: IMPORTE PAGADO | BF5: DIFERENCIA
A6: 43476 | B6: 43481 | C6: 43507 | D6: 43509 | E6: 43515 | F6: 92332682 | G6: PO 19-412 CONT 201 | H6: 92335771 | I6: PROGRESO | J6: 25526.04 | K6: AB.LOG | L6: =A6+60 -> 43536 | AZ6: =O6 -> 0 | BA6: 19.2524 | BB6: 1.1476 | BC6: 21.9858 | BD6: =+J6*BA6*BB6 -> 563973.71 | BE6: 557233.45 | BF6: =+BE6-BD6 -> -6740.2623
A7: 43476 | B7: 43481 | C7: 43507 | D7: 43509 | E7: 43515 | F7: 92332683 | G7: PO 19-413 CONT 204 | H7: 92336448 | I7: PROGRESO | J7: 22632 | K7: PALACE | L7: =A7+60 -> 43536 | AZ7: =O7 -> 0 | BA7: 19.2524 | BB7: 1.1476 | BC7: 21.9858 | BD7: =+J7*BA7*BB7 -> 500032.64 | BE7: 494735.52 | BF7: =+BE7-BD7 -> -5297.1156
A8: 43482 | B8: 43488 | C8: 43514 | D8: 43523 | E8: 43529 | F8: 92333464 | G8: PO 19-414 CONT 202 | H8: 92338345 | I8: PROGRESO | J8: 22632 | K8: PALACE | L8: =A8+60 -> 43542 | AZ8: =O8 -> 0 | BA8: 19.1185 | BB8: 1.1476 | BC8: 21.9013 | BD8: =+J8*BA8*BB8 -> 496554.92 | BE8: 487945.92 | BF8: =+BE8-BD8 -> -8609.0001
A9: 43475 | B9: 43481 | C9: 43500 | E9: 43509 | F9: 92333462 | G9: PO 19-415 CONT 203 | H9: 92335330 | I9: VERACRUZ | J9: 22737.96 | K9: XALAPA | L9: =A9+60 -> 43535 | AZ9: =O9 -> 0 | BA9: 19.0824 | BB9: 1.1434 | BC9: 21.6148 | BD9: =+J9*BA9*BB9 -> 496115.37 | BE9: 496597.05 | BF9: =+BE9-BD9 -> 481.68091
A10: 43496 | B10: 43502 | C10: 43522 | D10: 43525 | E10: 43531 | F10: 92336475 | G10: PO 19-416 CONT 205 | H10: 92344683 | I10: ALTAMIRA | J10: 22389.03 | K10: MAB | L10: =A10+60 -> 43556 | AZ10: =P10 -> 0 | BA10: 19.163 | BB10: 1.1476 | BC10: 21.989 | BD10: =+J10*BA10*BB10 -> 492367.43 | BE10: =+J10*21.535 -> 482147.76 | BF10: =+BE10-BD10 -> -10219.67
A11: 43496 | B11: 43502 | C11: 43521 | E11: 43525 | F11: 92337118 | G11: PO 19-417 CONT 206 | H11: 92344706 | I11: VERACRUZ | J11: 23941.6 | K11: MAB | L11: =A11+60 -> 43556 | AZ11: =P11 -> 0 | BA11: 19.2652 | BB11: 1.1476 | BC11: 21.7263 | BD11: =+J11*BA11*BB11 -> 529318.69 | BE11: =+J11*21.535 -> 515582.36 | BF11: =+BE11-BD11 -> -13736.338
A12: 43517 | B12: 43521 | C12: 43544 | E12: 43550 | F12: 92346985 | G12: PO 19-418 CONT 207 | H12: 92353879 | I12: PROGRESO | J12: 27290.28 | K12: AB.LOG | L12: =#REF!+60 -> #REF! | AZ12: =P12 -> 0 | BA12: 19.3233 | BB12: 1.13855 | BC12: 21.575 | BD12: =+J12*BA12*BB12 -> 600400.98 | BE12: 579099.74 | BF12: =+BE12-BD12 -> -21301.244
A13: 43517 | B13: 43523 | C13: 43543 | D13: 43544 | E13: 43554 | F13: 92348015 | G13: PO 19-419 CONT 208 | H13: 92353914 | I13: ALTAMIRA | J13: 21302.04 | K13: MAB | L13: =#REF!+60 -> #REF! | AZ13: =P13 -> 0 | BA13: 19.2176 | BB13: 1.1385 | BC13: 21.4796 | BD13: =+J13*BA13*BB13 -> 466072.39 | BE13: 452029.29 | BF13: =+BE13-BD13 -> -14043.105
A14: 43517 | B14: 43523 | C14: 43543 | D14: 43544 | E14: 43556 | F14: 92348012 | G14: PO 19-420 CONT 209 | H14: 92353960 | I14: ALTAMIRA | J14: 21254.33 | K14: MAB | L14: =#REF!+60 -> #REF! | AZ14: =P14 -> 0 | BA14: 19.2176 | BB14: 1.13855 | BC14: 21.4796 | BD14: =+J14*BA14*BB14 -> 465048.96 | BE14: =+J14*21.2279 -> 451184.79 | BF14: =+BE14-BD14 -> -13864.167
A15: 43518 | B15: 43523 | C15: 43542 | D15: 43546 | E15: 43546 | F15: 92348041 | G15: PO 19-421 CONT 210 | H15: 92354411 | I15: VERACRUZ | J15: 24011.28 | K15: MAB | L15: =A15+60 -> 43578 | AZ15: =P15 -> 0 | BA15: 19.3233 | BB15: 1.13855 | BC15: 21.575 | BD15: =+J15*BA15*BB15 -> 528261.2 | BE15: =+J15*21.2801 -> 510962.44 | BF15: =+BE15-BD15 -> -17298.764
A16: 43516 | B16: 43523 | C16: 43542 | D16: 43546 | E16: 43551 | F16: 92351054 | G16: PO 19-422 CONT 211 | H16: 92353217 | I16: VERACRUZ | J16: 23010 | K16: XALAPA | L16: =#REF!+60 -> #REF! | AZ16: =P16 -> 0 | BA16: 19.3233 | BB16: 1.13855 | BC16: 21.575 | BD16: =+J16*BA16*BB16 -> 506232.5 | BE16: =+J16*21.3515 -> 491298.02 | BF16: =+BE16-BD16 -> -14934.484
A17: 43538 | B17: 43544 | C17: 43564 | E17: 43571 | F17: 92356355 | G17: PO 19-423 CONT 212 | H17: 92363190 | I17: ALTAMIRA | J17: 21445.02 | K17: MAB | L17: =A17+60 -> 43598 | AZ17: =Q17 -> 0 | BA17: 18.9701 | BB17: 1.12265 | BC17: 21.2385 | BD17: =+J17*BA17*BB17 -> 456709.93 | BE17: =+J17*21.38 -> 458494.53 | BF17: =+BE17-BD17 -> 1784.5953
A18: 43552 | B18: =C18-21 -> 43558 | C18: 43579 | E18: 43585 | F18: 92364276 | G18: PO 19-424 CONT 213 | H18: 92369566 | I18: PROGRESO | J18: 27280.86 | K18: AB.LOG | L18: =A18+60 -> 43612 | AZ18: =Q18 -> 0 | BA18: 18.8359 | BB18: 1.12265 | BC18: 21.3023 | BD18: =+J18*BA18*BB18 -> 576884.42 | BE18: =+J18*21.3389 -> 582143.54 | BF18: =+BE18-BD18 -> 5259.1187
A19: =L19-60 -> #REF! | B19: 43565 | C19: 43584 | E19: 43588 | F19: 92366830 | G19: PO 19-425 CONT 214 | H19: 92373182 | I19: VERACRUZ | J19: 23898.48 | K19: XALAPA | L19: =#REF!+60 -> #REF! | AZ19: =R19 -> 0 | BA19: 19.0942 | BB19: 1.12265 | BC19: 21.206 | BD19: =+J19*BA19*BB19 -> 512290.29 | BE19: =+J19*21.9441 -> 524430.63 | BF19: =+BE19-BD19 -> 12140.341
A20: 43564 | B20: 43570 | C20: 43593 | E20: 42505 | F20: 92371475 | G20: PO 19-426 CONT 215 | H20: 92374654 | I20: PROGRESO | J20: 22632 | K20: PALACE | L20: =A20+60 -> 43624 | AZ20: =R20 -> 0 | BA20: 19.0012 | BB20: 1.12265 | BC20: 21.3983 | BD20: =+J20*BA20*BB20 -> 482778.97 | BE20: =+J20*21.7 -> 491114.4 | BF20: =+BE20-BD20 -> 8335.4294
A21: 43594 | B21: 43599 | C21: 43621 | E21: 43628 | F21: 92375232 | G21: PO 19-427 CONT 216 | H21: 92387912 | I21: PROGRESO | J21: 23263.2 | K21: PALACE | L21: =A21+60 -> 43654 | AZ21: =S21 -> 0 | BA21: 19.6426 | BB21: 1.12085 | BC21: 22.0674 | BD21: =+J21*BA21*BB21 -> 512172.11 | BE21: =+J21*21.21 -> 493412.47 | BF21: =+BE21-BD21 -> -18759.635
A22: 43570 | B22: 43572 | C22: 43591 | E22: 43598 | F22: 92373782 | G22: PO 19-428 CONT 217 | H22: 92376991 | I22: VERACRUZ | J22: 20577.72 | K22: XALAPA | L22: =A22+60 -> 43630 | BA22: 18.9781 | BB22: 1.12085 | BC22: 21.3311 | BD22: =+J22*BA22*BB22 -> 437721.1 | BE22: =+J22*21.56 -> 443655.64 | BF22: =+BE22-BD22 -> 5934.5448
A23: 43587 | B23: 43593 | C23: 43613 | E23: 43621 | F23: 92375946 | G23: PO 19-429 CONT 218 | H23: 92385058 | I23: ALTAMIRA | J23: 21767.65 | K23: MAB | L23: =A23+60 -> 43647 | AZ23: =S23 -> 0 | BA23: 19.0122 | BB23: 1.12085 | BC23: 21.3231 | BD23: =+J23*BA23*BB23 -> 463864.8 | BE23: =+J23*21.555 -> 469201.7 | BF23: =+BE23-BD23 -> 5336.8973
A24: 43585 | B24: 43592 | C24: 43614 | E24: 43622 | F24: 92351805 | G24: PO 19-430 CONT 219 | H24: 92383794 | I24: PROGRESO | J24: 26437.94 | K24: AB.LOG | L24: =#REF!+60 -> #REF! | BA24: 19.0685 | BB24: 1.12085 | BC24: 21.4439 | BD24: =+J24*BA24*BB24 -> 565056.19 | BE24: =+J24*21.6 -> 571059.5 | BF24: =+BE24-BD24 -> 6003.31
A25: 43598 | B25: 43600 | C25: 43619 | E25: 43621 | F25: 92382444 | G25: PO 19-431 CONT 220 | H25: 92389022 | I25: VERACRUZ | J25: 22752.91 | K25: VER | L25: =A25+60 -> 43658 | AZ25: =S25 -> 0 | BA25: 19.0683 | BB25: 1.12085 | BC25: 22.1016 | BD25: =+J25*BA25*BB25 -> 486291.21 | BE25: =+J25*21.3815 -> 486491.35 | BF25: =+BE25-BD25 -> 200.13334
A26: 43608 | B26: 43612 | C26: 43634 | E26: 43645 | F26: 92391687 | G26: PO 19-432 CONT 221 | H26: 92394345 | I26: PROGRESO | J26: 24011.04 | K26: SOLULOGIS | L26: =#REF!+60 -> #REF! | AZ26: =S26 -> 0 | BA26: 19.1487 | BB26: 1.1146 | BC26: 21.3971 | BD26: =+J26*BA26*BB26 -> 512471.01 | BE26: =+J26*21.3371 -> 512325.96 | BF26: =+BE26-BD26 -> -145.05117
A27: 43620 | B27: 43626 | C27: 43649 | E27: 43655 | F27: 923911237 | G27: PO 19-433 CONT 222 | H27: 92399437 | I27: PROGRESO | J27: 25632.12 | K27: AB.LOG | L27: =A27+60 -> 43680 | AZ27: =T27 -> 0 | BA27: 19.2087 | BB27: 1.1146 | BC27: 21.5456 | BD27: =+J27*BA27*BB27 -> 548784.13 | BE27: =+J27*21.2333 -> 544254.49 | BF27: =+BE27-BD27 -> -4529.6319
A28: 43622 | B28: 43626 | C28: 43649 | E28: 43655 | F28: 92397182 | G28: PO 19-434 CONT 223 | H28: 92400777 | I28: PROGRESO | J28: 24490.5 | K28: MERIDA | L28: =A28+60 -> 43682 | AZ28: =T28 -> 0 | BA28: 19.2087 | BB28: 1.1146 | BC28: 21.5456 | BD28: =+J28*BA28*BB28 -> 524342.02 | BE28: =+J28*21.5539 -> 527865.79 | BF28: =+BE28-BD28 -> 3523.7661
A29: 43636 | B29: 43642 | C29: 43661 | E29: 43665 | F29: 92401346 | G29: PO 19-435 CONT 224 | H29: 92407480 | I29: VERACRUZ | J29: 21103.2 | K29: XALAPA | L29: =A29+60 -> 43696 | AZ29: =T29 -> 0 | BA29: 19.1227 | BB29: 1.1386 | BC29: 21.406 | BD29: =+J29*BA29*BB29 -> 459482.22 | BE29: =+J29*22.12 -> 466802.78 | BF29: =+BE29-BD29 -> 7320.5688
A30: 43635 | B30: 43640 | C30: 43663 | E30: 43669 | F30: 92401347 | G30: PO 19-436 CONT 225 | H30: 92406517 | I30: PROGRESO | J30: 26779.92 | K30: AB.LOG | L30: =A30+60 -> 43695 | AZ30: =T30 -> 0 | BA30: 19.0307 | BB30: 1.13865 | BC30: 21.4123 | BD30: =+J30*BA30*BB30 -> 580302.3 | BE30: =+J30*21.4411 -> 574190.94 | BF30: =+BE30-BD30 -> -6111.3533
A31: 43656 | B31: 43661 | C31: 43683 | E31: 43693 | F31: 92412211 | G31: PO 19-437 CONT 226 | H31: 92416086 | I31: PROGRESO | J31: 22852.8 | K31: PALACE | L31: =A31+60 -> 43716 | AZ31: =U31 -> 0 | BA31: 19.3116 | BB31: 1.13865 | BC31: 21.9875 | BD31: =+J31*BA31*BB31 -> 502513.72 | BE31: =+J31*21.5889 -> 493366.81 | BF31: =+BE31-BD31 -> -9146.9095
A32: 43678 | B32: 43682 | C32: 43705 | E32: 43711 | F32: 92417291 | G32: PO 19-438 CONT 227 | H32: 92426478 | I32: PROGRESO | J32: =9.2*2472 -> 22742.4 | K32: PALACE | L32: =A32+60 -> 43738 | AZ32: =U32 -> 0 | BA32: 19.9089 | BB32: 1.1135 | BC32: 22.2218 | BD32: =+J32*BA32*BB32 -> 504166.26 | BE32: =+J32*21.538 -> 489825.81 | BF32: =+BE32-BD32 -> -14340.451
A33: 43672 | B33: 43677 | C33: 43696 | E33: 43700 | F33: 92418730 | G33: PO 19-439 CONT 228 | H33: 92423908 | I33: VERACRUZ | J33: 23103.48 | K33: VER | L33: =A33+60 -> 43732 | AZ33: =U33 -> 0 | BA33: 19.6365 | BB33: 1.1135 | BC33: 22.0118 | BD33: =+J33*BA33*BB33 -> 505163.2 | BE33: =+J33*21.42 -> 494876.54 | BF33: =+BE33-BD33 -> -10286.657
A34: 43692 | B34: 43696 | C34: 43721 | E34: 43725 | F34: 92426567 | G34: PO 19-441 CONT 230 | H34: 92432777 | I34: PROGRESO | J34: 27455.76 | K34: AB.LOG | L34: =A34+60 -> 43752 | AZ34: =V34 -> 0 | BA34: 19.5398 | BB34: 1.10155 | BC34: 21.5172 | BD34: =+J34*BA34*BB34 -> 590959.61 | BE34: =+J34*21.4196 -> 588091.4 | BF34: =+BE34-BD34 -> -2868.2124
A35: 43700 | B35: 43705 | C35: 43726 | E35: 43731 | F35: 92431557 | G35: PO 19-440 CONT 229 | H35: 92436295 | I35: ALTAMIRA | J35: 20376.81 | K35: MAB | L35: 43760 | AZ35: =V35 -> 0 | BA35: 19.4265 | BB35: 1.10155 | BC35: 21.4154 | BD35: =+J35*BA35*BB35 -> 436048.68 | BE35: =+J35*21.3586 -> 435220.13 | BF35: =+BE35-BD35 -> -828.543
A36: 43717 | B36: 43719 | C36: 43739 | D36: 43738 | E36: 43742 | F36: 92438514 | G36: PO 19-442 CONT 231 | H36: 92443563 | I36: VERACRUZ | J36: 20475.48 | K36: MAB Y 3TEMP | L36: =A36+60 -> 43777 | AZ36: =W36 -> 0 | BA36: 19.6363 | BB36: 1.10155 | BC36: 21.554 | BD36: =+J36*BA36*BB36 -> 442892.13 | BE36: =+J36*21.2045 -> 434172.32 | BF36: =+BE36-BD36 -> -8719.8162
A37: 43738 | B37: 43740 | C37: 43760 | E37: 43762 | F37: 92447389 | G37: PO 19-443 CONT 232 | H37: 92452704 | I37: VERACRUZ | J37: 19908.04 | K37: 3TD Y POLLO | L37: =A37+60 -> 43798 | AZ37: =W37 -> 0 | BA37: 19.1605 | BB37: 1.09025 | BC37: 21.3675 | BD37: =+J37*BA37*BB37 -> 415873.68 | BE37: =+J37*21.3767 -> 425568.2 | BF37: =+BE37-BD37 -> 9694.5162
A38: 43766 | B38: 43768 | C38: 43788 | D38: 43787 | E38: 43790 | F38: 92458284 | G38: PO 19-444 CONT 233 | H38: 92465668 | I38: VERACRUZ | J38: 19811.16 | K38: 3TD Y MAB | L38: =A38+60 -> 43826 | AZ38: =X38 -> 0 | BA38: 19.4228 | BB38: 1.11405 | BC38: 21.4557 | BD38: =+J38*BA38*BB38 -> 428673.29 | BE38: =+J38*21.2204 -> 420400.74 | BF38: =+BE38-BD38 -> -8272.5528
A39: 43767 | B39: 43773 | C39: 43796 | E39: 43805 | F39: 92463052 | G39: PO 19-446 CONT 234 | H39: 92466697 | I39: PROGRESO | J39: 23541 | K39: AB.LOG | L39: =A39+60 -> 43827 | AZ39: =X39 -> 0 | BA39: 19.4468 | BB39: 1.11405 | BC39: 21.5314 | BD39: =+J39*BA39*BB39 -> 510008.88 | BE39: =+J39*21.2097 -> 499297.55 | BF39: =+BE39-BD39 -> -10711.332
A40: 43780 | B40: 43783 | C40: 43802 | E40: 43806 | F40: 92471542 | G40: PO 19-477 CONT 235 | H40: 92472558 | I40: VERACRUZ | J40: 19829.52 | K40: 3TD Y MAB | L40: =A40+60 -> 43840 | AZ40: =Y40 -> 0 | BA40: 19.5352 | BB40: 1.11405 | BC40: 21.6723 | BD40: =+J40*BA40*BB40 -> 431553.6 | BE40: =+J40*21.3 -> 422368.78 | BF40: =+BE40-BD40 -> -9184.8266
A41: 43780 | B41: 43782 | C41: 43803 | E41: 43809 | F41: 92469631 | G41: PO 19-445 CONT 240 | H41: 92472610 | I41: ALTAMIRA | J41: 19381.56 | K41: MAB | L41: =A41+60 -> 43840 | AZ41: =Y41 -> 0 | BA41: 19.5717 | BB41: 1.11405 | BC41: 21.5541 | BD41: =+J41*BA41*BB41 -> 422592.67 | BE41: =+J41*21.0638 -> 408249.3 | BF41: =+BE41-BD41 -> -14343.37
...

Sheet CUENTAS X PAGAR WERNSING
A1: OXDA SA DE CV
A2: WERNSING FEINKOST GMOH
A4: WERNSING | M4: 2020 | N4: 2020 | O4: 2020 | P4: 2020 | Q4: 2020 | R4: 2020 | S4: 2020 | T4: 2020 | U4: 2020 | V4: 2020 | W4: 2020 | X4: 2020 | Y4: 2021 | Z4: 2021 | AA4: 2021 | AB4: 2021 | AC4: 2021 | AD4: 2021 | AE4: 2021 | AF4: 2021 | AG4: 2021 | AH4: 2021 | AI4: 2021 | AJ4: 2021 | AK4: 2022 | AM4: FIX (PEDIMENTO) | AN4: FACTOR MON.FACT | AO4: T.C. EUR | AP4: PROM. DE COMPRA | AQ4: IMPORTE PAGADO | AR4: DIFERENCIA
A5: FECHA FACTURA | B5: ETD | C5: ETA | D5: ETA REAL | E5: ETA ALMACEN | F5: PROFORMA | G5: CONTENEDOR | H5: FACTURA | I5: DESTINO | J5: IMPORTE | K5: CLIENTE | L5: FECHA DE VENCIMIENTO FACTURA | M5: ENE | N5: FEB | O5: MAR | P5: ABR | Q5: MAY | R5: JUN | S5: JUL | T5: AGO | U5: SEP | V5: OCT | W5: NOV | X5: DIC | Y5: ENE | Z5: FEB | AA5: MAR | AB5: APR | AC5: MAY | AD5: JUN | AE5: JUL | AF5: AUG | AG5: SEP | AH5: OCT | AI5: NOV | AJ5: DEC | AK5: ENE | AL5: TOTAL
A6: 44099 | B6: 44104 | C6: 44133 | G6: P.O.21-001 CONT 01W | H6: 20569124 | I6: VERACRUZ | J6: =17649+245.2 -> 17894.2 | K6: ? | L6: =A6+45 -> 44144 | AL6: =W6 -> 0 | AM6: 21.377 | AN6: 1.17275 | AO6: 24.7699 | AQ6: 445334.64
A7: 44140 | B7: 44143 | C7: 44165 | G7: P.O.20-002 CONT 02W | H7: 20577433 | I7: PROGRESO | J7: 19234.8 | K7: ? | L7: =A7+45 -> 44185 | AL7: =X7 -> 0 | AM7: 20.0467 | AN7: 1.16785 | AO7: =AN7*AM7 -> 23.411539
A8: 44194 | B8: 44200 | C8: 44221 | G8: P.O.20-003 CONT 03W | H8: 20586513 | I8: PROGRESO | J8: 16632 | K8: Faraon / Meloni | L8: =A8+45 -> 44239 | AL8: =X8 -> 0 | AM8: 19.7393 | AN8: 1.2234 | AO8: =AM8*AN8 -> 24.14906
A9: 44228 | B9: =C9-20 -> 44229 | C9: 44249 | G9: P.O.21-004 CONT 04W | H9: 21592448 | I9: PROGRESO | J9: 17808.6 | L9: =A9+45 -> 44273 | Q9: =J9 -> 17808.6 | AL9: =X9 -> 0 | AM9: 20.4165 | AN9: 1.2146 | AO9: =AM9*AN9 -> 24.797881
A10: 44316 | B10: =C10-22 -> 44324 | C10: 44346 | F10: 308953 | G10: P.O.21-005 CONT 05W | H10: 21609532 | I10: PROGRESO | J10: 17344.8 | K10: FARAON | L10: =A10+45 -> 44361 | AL10: =AD10 -> 0 | AM10: 20.0495 | AN10: 1.20405 | AO10: =AN10*AM10 -> 24.1406
A11: 44306 | B11: 44310 | C11: 44332 | F11: 315007 | G11: P.O.21-006 CONT 06W | H11: 21607276 | I11: PROGRESO | J11: 21276 | K11: MELONI | L11: =A11+45 -> 44351 | AL11: =AD11 -> 0
A12: 44432 | B12: 44426 | C12: 44458 | F12: 382734 | G12: P.O.21-007 CONT 07W | H12: 21635163 | I12: PROGRESO | J12: 21207.6 | L12: =A12+45 -> 44477 | AL12: =AH12 -> 0
A13: 44440 | B13: 44443 | C13: 44460 | F13: 390236 | G13: P.O.21-008 CONT 08W | H13: 21638905 | I13: VERACRUZ | J13: 21391.2 | L13: =A13+45 -> 44485 | AL13: =AH13 -> 0
A14: 44490 | B14: 44492 | C14: 44514 | G14: P.O.21-009 CONT 09W | H14: 216488602 | I14: PROGRESO | J14: 21225.6 | L14: =A14+45 -> 44535 | AL14: =AJ14 -> 0
A15: 44476 | B15: 44478 | C15: 44495 | G15: P.O.21-010 CONT 10W | H15: 21645554 | I15: VERACRUZ | J15: 21513.6 | K15: LEÓN | L15: =A15+45 -> 44521 | AL15: =AI15 -> 0
A16: 44497 | B16: 44499 | C16: 44516 | G16: P.O.21-011 CONT 11W | H16: 21650243 | I16: VERACRUZ | J16: 22690.8 | K16: LEÓN | L16: =A16+45 -> 44542 | AJ16: 0 | AL16: =AJ16 -> 0
A17: 44588 | B17: 44620 | C17: 44632 | G17: P.O.21-012 CONT 12W | H17: 22669196 | I17: PROGRESO | J17: 22796.8 | K17: Faraon / Meloni | L17: =A17+45 -> 44633 | AK17: =J17 -> 22796.8 | AL17: =AK17 -> 22796.8
A18: 44603 | B18: 44612 | C18: 44632 | G18: P.O.22-013 CONT 13W | H18: 22672671 | I18: PROGRESO | J18: 22627.6 | K18: Abastos L | L18: =A18+45 -> 44648
A19: 44624 | B19: 44627 | C19: 44648 | G19: P.O.22-014 CONT 14W | H19: 22677663 | I19: ALTAMIRA | J19: 28478.6 | K19: Vulpes | L19: =A19+45 -> 44669
A20: 44657 | B20: 44655 | C20: 44681 | F20: 497593 | G20: P.O.22-015 CONT 15W | H20: 22684712 | I20: PROGRESO | J20: 26683 | K20: Abastos L | L20: =A20+45 -> 44702
A21: 44679 | B21: 44681 | C21: 44704 | G21: P.O.22-016 CONT 16W | H21: 22689326 | I21: PROGRESO | J21: 27093.4 | K21: Palace | L21: =A21+45 -> 44724
A22: 44685 | B22: 44688 | C22: 44711 | G22: P.O. 22-017 CONT 17W | H22: 22689325 | I22: PROGRESO | J22: 29528.2 | K22: Abastos L | L22: =A22+45 -> 44730
A23: 44699 | B23: 44702 | C23: 44723 | G23: P.O. 22-018 CONT 18W | H23: 22693735 | I23: PROGRESO | J23: 29294.2 | K23: Palace | L23: =A23+45 -> 44744
A24: 44699 | B24: 44702 | C24: 44723 | G24: P.O. 22-019 CONT 19W | H24: 22693479 | I24: PROGRESO | J24: 29294.2 | K24: Palace | L24: =A24+45 -> 44744
A25: 44698 | B25: 44702 | C25: 44723 | G25: P.O. 22-020 CONT 20W | H25: 22693463 | I25: PROGRESO | J25: 22075.2 | K25: Abastos L | L25: =A25+45 -> 44743
A26: 44761 | B26: 44762 | C26: 44787 | F26: 563074 | G26: P.O. 22-021 CONT 21W | H26: 22706969 | I26: PROGRESO | J26: 31762 | K26: Abastos L | L26: =A26+45 -> 44806
A27: 44770 | B27: 44772 | C27: 44793 | G27: P.O. 22-022 CONT 22W | H27: 22709720 | I27: PROGRESO | J27: 33438.6 | K27: El Faraón | L27: =A27+45 -> 44815
A28: 44818 | C28: 44849 | F28: 582709 | G28: P.O. 23-022 CONT 23W | H28: 22719751 | I28: PROGRESO | J28: 33964.8 | K28: Palace | L28: =A28+45 -> 44863
A29: 44818 | C29: 44849 | F29: 582719 | G29: P.O. 24-022 CONT 24W | H29: 22719752 | I29: PROGRESO | J29: 35275.2 | K29: Abs. L./El Faraón | L29: =A29+45 -> 44863
A30: 44818 | C30: 44849 | F30: 582721 | G30: P.O. 25-022 CONT 25W | H30: 22719753 | I30: PROGRESO | J30: 35174.4 | K30: Abastos L | L30: =A30+45 -> 44863
C36: IMPORTE TOTAL | J36: =SUM(J6:J30) -> 625705.4 | N36: =SUM(N6:N30) -> 0 | O36: =SUM(O6:O30) -> 0 | P36: =SUM(P6:P30) -> 0 | Q36: =SUM(Q6:Q30) -> 17808.6 | R36: =SUM(R6:R30) -> 0 | S36: =SUM(S6:S30) -> 0 | T36: =SUM(T6:T30) -> 0 | U36: =SUM(U6:U30) -> 0 | ... AA36: =SUM(AA6:AA30) -> 0 | AL36: =SUM(AL6:AL30) -> 22796.8

Sheet Cancun.
A1: OXDA S.A. DE C.V.
A2: CONSUMO ABASTOS LOGICOS
C4: CAJAS POR PALLET. | D4: NUMERO DE PALLETS | E4: CONTENEDOR ETA 17 OCT. | F4: NUMETO DE PALLETS | G4: CONTENEDOR ETA 14 NOV. | H4: NUMERO DE PALLETS | I4: CONTENEDOR ETA 12 DIC. | J4: NUMERO DE PALLETS | K4: CONTENEDOR ETA 12 DIC.
A5: CODIGO | B5: CONCEPTO
A6: 802142 | B6: AVIKO STRAIGHT CUT 3/8 4X2500G REG3 | C6: 120 | E6: =+D6*C6 -> 0 | G6: =+C6*F6 -> 0 | I6: =+C6*H6 -> 0 | K6: =+C6*J6 -> 0
A7: 804104 | B7: AVIKO HASH BROWNS TRIANGLES 4X2500G | C7: 108 | E7: =+D7*C7 -> 0 | G7: =+C7*F7 -> 0 | I7: =+C7*H7 -> 0 | K7: =+C7*J7 -> 0
A8: 805567 | B8: AVIKO RÖSTIKO ROUNDS FRYER 4X2500G | C8: 108 | E8: =+D8*C8 -> 0 | G8: =+C8*F8 -> 0 | I8: =+C8*H8 -> 0 | K8: =+C8*J8 -> 0
A9: 806671 | B9: AVIKO SPICY JACKET WEDGES 4X2500G | C9: 120 | E9: =+D9*C9 -> 0 | G9: =+C9*F9 -> 0 | I9: =+C9*H9 -> 0 | K9: =+C9*J9 -> 0
A10: 806685 | B10: AVIKO H PREM. CRUNCH SHOESTRING 7MM 4X2270g | C10: 96 | E10: =+D10*C10 -> 0 | G10: =+C10*F10 -> 0 | I10: =+C10*H10 -> 0 | K10: =+C10*J10 -> 0
A11: 806686 | B11: AVIKO H SUPER CRUNCH 9.5MM 3/8 4X2500G | C11: 96 | E11: =+D11*C11 -> 0 | G11: =+C11*F11 -> 0 | I11: =+C11*H11 -> 0 | K11: =+C11*J11 -> 0
A12: 806982 | B12: AVIKO BREADED ONION RINGS 6*1000 G | C12: 120 | E12: =+D12*C12 -> 0 | G12: =+C12*F12 -> 0 | I12: =+C12*H12 -> 0 | K12: =+C12*J12 -> 0
A13: 807329 | B13: AVIKO ORIGINAL 20X450 G. | C13: 120 | E13: =+D13*C13 -> 0 | F13: 0 | G13: =+C13*F13 -> 0 | I13: =+C13*H13 -> 0 | J13: 0 | K13: =+C13*J13 -> 0
D14: =SUM(D6:D13) -> 0 | E14: =SUM(E6:E13) -> 0 | F14: =SUM(F6:F13) -> 0 | G14: =SUM(G6:G13) -> 0 | H14: =SUM(H6:H13) -> 0 | I14: =SUM(I6:I13) -> 0 | J14: =SUM(J6:J13) -> 0 | K14: =SUM(K6:K13) -> 0
D21: Puerto | E21: Fecha ETD | F21: Fecha ETA | G21: Pedido | H21: Contenedor
D22: Progreso | E22: 44464 | F22: 44486 | G22: 21-502 | H22: C-291 | I22: ABASTOS LOG | J22: Entregado
D23: Progreso | E23: 44486 | F23: 44507 | G23: 21-506 | H23: C-295 | I23: ABASTOS LOG | J23: Entregado
D24: Progreso | E24: 44538 | F24: 44565 | G24: 21-511 | H24: C-300 | I24: ABASTOS LOG | J24: Confirmado
D25: Progreso | E25: 44542 | F25: 44563 | G25: 21-514 | H25: C-303 | I25: ABASTOS LOG

Sheet 3TD.
B2: OXDA S.A. DE C.V.
B3: CONSUMO VERACRUZ.
D5: CAJAS POR PALLET. | E5: NUMERO DE PALLETS. | F5: ENTRADA CONTENEDOR 04/10/2021 | G5: NUMERO DE PALLETS | H5: ENTRADA CONTENEDOR 08/11/2021 | I5: NUMETO DE PALLETS | J5: ENTRADA CONTENEDOR 13/12/2021 | K5: NUMERO DE PALLETS
B6: CODIGO | C6: CONCEPTO
B7: 806685 | C7: AVIKO H PREM. CRUNCH SHOESTRING 7MM 4X2270g | D7: 108 | L7: =+D7*K7 -> 0
B8: 806939 | C8: AVIKO CRINKLE CUT 12MM 4 X 2.5 KG | D8: 108 | L8: =+D8*K8 -> 0
B9: 804661 | C9: AVIKO STEAK FRIES 4X2500G 4X5.5 LBS | D9: 120
E10: =SUM(E7:E9) -> 0 | F10: =SUM(F7:F9) -> 0 | G10: =SUM(G7:G9) -> 0 | H10: =SUM(H7:H9) -> 0 | I10: =SUM(I7:I9) -> 0 | J10: =SUM(J7:J9) -> 0 | K10: =SUM(K7:K8) -> 0 | L10: =SUM(L7:L8) -> 0
D15: Puerto | E15: Fecha ETD | F15: Fecha ETA | G15: Pedido | H15: Contenedor
D16: Veracruz | E16: 44475 | F16: 44494 | G16: 21-503 | H16: C-292 | I16: 3TD | J16: Entregado
D17: Veracruz | E17: 44498 | F17: 44518 | G17: 21-508 | H17: C-297 | I17: 3TD | J17: Confirmado
D18: Veracruz | E18: 44523 | F18: 44543 | G18: 21-513 | H18: C-302 | I18: 3TD
D19: Veracruz | E19: 44482 | F19: 44508 | G19: 21-516 | H19: C-305 | I19: 3TD | J19: Confirmado

Sheet 3B
B2: OXDA S.A. DE C.V.
B3: CONSUMO VERACRUZ.
D5: CAJAS POR PALLET. | E5: NUMERO DE PALLETS. | F5: ENTRADA CONTENEDOR 15/10/2021 | G5: NUMERO DE PALLETS | H5: ENTRADA CONTENEDOR 05/11/2021 | I5: NUMETO DE PALLETS | J5: ENTRADA CONTENEDOR 03/12/2021 | K5: NUMERO DE PALLETS | L5: ENTRADA CONTENEDOR 07/01/2022
B6: CODIGO | C6: CONCEPTO
B7: 807769 | C7: AVIKO STRAIGHT CUT (10X1000G) | D7: 120 | E7: 17
B8: 807329 | C8: AVIKO ORIGINAL 20X450 G. | D8: 120 | E8: 4
B9: 805411 | C9: AVIKO PAPAS FRITAS ZIGZAG 12X750G | D9: 108
E10: =SUM(E7:E9) -> 21 | F10: =SUM(F7:F9) -> 0 | G10: =SUM(G7:G9) -> 0 | H10: =SUM(H7:H9) -> 0 | I10: =SUM(I7:I9) -> 0 | J10: =SUM(J7:J9) -> 0 | K10: =SUM(K7:K9) -> 0 | L10: =SUM(L7:L9) -> 0
E16: Puerto | F16: Fecha ETD | G16: Fecha ETA | H16: Pedido | I16: Contenedor
E17: Veracruz | F17: 44475 | G17: 44492 | H17: 21-501 | I17: C-290 A | J17: 3B | K17: Entregado
E18: Veracruz | F18: 44475 | G18: 44508 | H18: 21-501 | I18: C-290 B | J18: 3B | K18: Confirmado
E19: Veracruz | F19: 44494 | G19: 44514 | H19: 21-505 | I19: C-294 | J19: 3B | K19: Confirmado
E20: Veracruz | F20: 44513 | G20: 44533 | H20: 21-510 | I20: C-299 | J20: 3B
E21: Veracruz | F21: 44548 | G21: 44568 | H21: 21-515 | I21: C-304 | J21: 3B

Sheet Mazatlan.
C3: OXDA S.A. DE C.V.
C4: CONSUMO MAZATLAN
E6: CAJAS POR PALLET. | F6: NUMERO DE PALLETS. | G6: ENTRADA CONTENEDOR 10/10/2021 | H6: NUMERO DE PALLETS | I6: ENTRADA CONTENEDOR 10/11/2021 | J6: NUMETO DE PALLETS | K6: ENTRADA CONTENEDOR 01/12/2021 | L6: NUMERO DE PALLETS | M6: ENTRADA CONTENEDOR 15/12/2021
C7: CODIGO | D7: CONCEPTO
C8: 807679 | D8: AVIKO SPICY WEDGES 20X500G | E8: 120 | F8: 3 | G8: =+$E$8*F8 -> 360 | H8: 3 | I8: =+$E$8*H8 -> 360 | J8: 3 | K8: =+$E$8*J8 -> 360 | L8: 3 | M8: =+$E$8*L8 -> 360
C9: 807769 | D9: AVIKO STRAIGHT CUT (10X1000G) | E9: 120 | F9: 5 | G9: =+$E$8*F9 -> 600 | H9: 5 | I9: =+$E$8*H9 -> 600 | J9: 5 | K9: =+$E$8*J9 -> 600 | L9: 5 | M9: =+$E$8*L9 -> 600
C10: 807329 | D10: AVIKO ORIGINAL 20X450 G. | E10: 120 | F10: 12 | G10: =+$E$8*F10 -> 1440 | H10: 12 | I10: =+$E$8*H10 -> 1440 | J10: 12 | K10: =+$E$8*J10 -> 1440 | L10: 12 | M10: =+$E$8*L10 -> 1440
C11: 805168 | D11: AVIKO ANEIS DE CEBOLA 25X400G | E11: 120 | F11: 1 | G11: =+$E$8*F11 -> 120 | H11: 1 | I11: =+$E$8*H11 -> 120 | J11: 1 | K11: =+$E$8*J11 -> 120 | L11: 1 | M11: =+$E$8*L11 -> 120
F12: =SUM(F8:F11) -> 21 | G12: =SUM(G8:G11) -> 2520 | H12: =SUM(H8:H11) -> 21 | I12: =SUM(I8:I11) -> 2520 | J12: =SUM(J8:J11) -> 21 | K12: =SUM(K8:K11) -> 2520 | L12: =SUM(L8:L11) -> 21 | M12: =SUM(M8:M11) -> 2520

Sheet Hoja2
B1: ORDEN DE COMPRA | C1: INVOICE | D1: MONTO | E1: FECHA DE PAGO (SEGÚN FACTURA) | F1: FECHA DE PAGO CON 30 DÍAS DE CRÉDITO ADICIONALES
B2: P.O.22-525 C-314 | C2: 92864149 | D2: 26167.2 | E2: 44730 | F2: =+E2+30 -> 44760
B3: P.O.22-528 C-317 | C3: 92845157 | D3: 32938.2 | E3: 44731 | F3: =+E3+30 -> 44761
B4: P.O.22-531 C-320 | C4: 92855909 | D4: 31602.84 | E4: 44754 | F4: 44785
