Workbook

Sheet Resumen Inventario
B1: DICIEMBRE . 2025
A2: Cliente / Bodega | B2: Valo inventario | C2: Cajas en inventario | D2: Costo promedio | E2: Venta de cajas del mes | G2: Llegadas | H2: Ventas estimadas | I2: Inv actual + llegadas | J2: Inv - ventas estimadas
A3: Abastos logicos
A4: CDMX: Arcosa | Fresco | Frigarsa | Canbelt
A5: Bajo Cero
A6: Frjalisco
A7: Alfrimex
A8: Vulpes
A9: Importe Total
B10: ENERO . 2026
A11: Cliente / Bodega | B11: Valo invent | C11: Cajas invent | D11: costo prom | E11: vta cajas mes | G11: Llegadas | H11: Ventas estimadas | I11: Inv actual + llegadas | J11: Inv - ventas estimadas
A12: Abastos logicos | B12: =+'$$$$$'!S22 -> 2232136.3 | C12: =+'$$$$$'!R22 -> 7406.75 | D12: =+B12/C12 -> 301.36514 | E12: =+CANCÚN!J26 -> 1803 | G12: 2268 | H12: 2000 | I12: =+G12+C12 -> 9674.75 | J12: =+I12-H12 -> 7674.75 | K12: =+J12/H12 -> 3.837375
A13: CDMX: Arcosa | Fresco | Frigarsa | Canbelt | B13: =+'$$$$$'!S46+'$$$$$'!S70+'$$$$$'!S94+'$$$$$'!S171 -> 1775097.1 | C13: =+'$$$$$'!T171+'$$$$$'!T94+'$$$$$'!T70+'$$$$$'!T46 -> 3774.6 | D13: =+B13/C13 -> 470.27424 | E13: =+'RESUMEN CDMX'!J26+FRIGARSA!G24+FRESCO!G25+CANBELT!L8 -> 1539.7 | G13: 2268 | H13: 1200 | I13: =+G13+C13 -> 6042.6 | J13: =+I13-H13 -> 4842.6 | K13: =+J13/H13 -> 4.0355
A14: Bajo Cero | B14: =+'$$$$$'!S139 -> 1544466.5 | C14: =+'$$$$$'!R139 -> 5539.16 | D14: =+B14/C14 -> 278.82685 | E14: =+'VULPES PAPAS'!G35 -> 2324.58 | H14: 3200 | I14: =+G14+C14 -> 5539.16 | J14: =+I14-H14 -> 2339.16 | K14: =+J14/H14 -> 0.7309875
A15: Frjalisco | B15: =+'$$$$$'!S112 -> 449970.4 | C15: =+'$$$$$'!R112 -> 1372 | D15: =+B15/C15 -> 327.96676 | E15: =+FRIJALISCO!J28 -> 2613 | H15: 2200 | I15: =+G15+C15 -> 1372 | J15: =+I15-H15 -> -828 | K15: =+J15/H15 -> -0.37636364
A16: Alfrimex | B16: =+'$$$$$'!S175 -> 94930.96 | C16: =+'$$$$$'!R174 -> 356 | D16: =+B16/C16 -> 266.66 | E16: =+ALFRIMEX!H8 -> 158 | H16: 50 | I16: =+G16+C16 -> 356 | J16: =+I16-H16 -> 306 | K16: =+J16/H16 -> 6.12
A17: Vulpes | B17: =+'$$$$$'!S167 -> 307923.39 | C17: =+'$$$$$'!R167 -> 980.84 | D17: =+B17/C17 -> 313.93845 | E17: 0 | I17: =+G17+C17 -> 980.84 | J17: =+I17-H17 -> 980.84
A18: Importe Total | B18: =+SUM(B12:B17) -> 6404524.7 | C18: =+SUM(C12:C17) -> 19429.35 | D18: =+AVERAGE(D12:D17) -> 326.50524 | E18: =+SUM(E12:E16) -> 8438.28 | G18: =+SUM(G12:G17) -> 4536 | H18: =+SUM(H12:H17) -> 8650 | J18: =+SUM(J12:J17) -> 15315.35 | K18: =+J18/H18 -> 1.7705607
B20: FEBRERO . 2026
A21: Cliente / Bodega | B21: Valo invent | C21: Cajas invent | D21: costo prom | E21: vta cajas mes | G21: Llegadas | H21: Ventas estimadas | I21: Inv actual + llegadas | J21: Inv - ventas estimadas
A22: Abastos logicos | B22: =+'$$$$$'!U22 -> 1713755.1 | C22: =+'$$$$$'!T22 -> 5630 | D22: =+B22/C22 -> 304.39699 | E22: =+CANCÚN!O26 -> 1776.75
A23: CDMX: Arcosa | Fresco | Frigarsa | Canbelt | B23: =+'$$$$$'!U198+'$$$$$'!U171+'$$$$$'!U94+'$$$$$'!U70+'$$$$$'!U46 -> 1961617.5 | C23: =+'$$$$$'!T46+'$$$$$'!T70+'$$$$$'!T94+'$$$$$'!T171+'$$$$$'!T198 -> 5822.6 | D23: =+B23/C23 -> 336.89718 | E23: =+'RESUMEN CDMX'!O26+FRIGARSA!L24+FRESCO!L25+MEXIDELI!L24+CANBELT!L8 -> 1420 | G23: 2198
A24: Bajo Cero | B24: =+'$$$$$'!U139 -> 1677356.5 | C24: =+'$$$$$'!T139 -> 6005.16 | D24: =+B24/C24 -> 279.31921 | E24: =+'VULPES PAPAS'!L35 -> 1353.18
A25: Frjalisco | B25: =+'$$$$$'!U112 -> 666908.8 | C25: =+'$$$$$'!T112 -> 2464 | D25: =+B25/C25 -> 270.66104 | E25: =+FRIJALISCO!O28 -> 1745
A26: Alfrimex | B26: =+'$$$$$'!U175 -> 11733.04 | C26: =+'$$$$$'!T175 -> 44 | D26: =+B26/C26 -> 266.66 | E26: 44
A27: Vulpes | B27: =+'$$$$$'!U167 -> 177402.69 | C27: =+'$$$$$'!T167 -> 641.32 | D27: =+B27/C27 -> 276.62118 | E27: 0
A28: Importe Total | B28: =SUM(B22:B27) -> 6208773.7 | C28: =SUM(C22:C27) -> 20607.08 | D28: =SUM(D22:D27) -> 1734.5556 | E28: =SUM(E22:E27) -> 6338.93
B30: MARZO . 2026
A31: Cliente / Bodega | B31: Valo invent | C31: Cajas invent | D31: costo prom | E31: vta cajas mes | G31: Llegadas | H31: Ventas estimadas | I31: Inv actual + llegadas | J31: Inv - ventas estimadas
A32: Abastos logicos | B32: =+'$$$$$'!W22 -> 911559.38 | C32: =+'$$$$$'!V22 -> 2875.25 | D32: =+B32/C32 -> 317.03656 | E32: =+CANCÚN!T26 -> 2764.75
A33: CDMX: Arcosa | Fresco | Frigarsa | Canbelt | B33: =+'$$$$$'!W46+'$$$$$'!W70+'$$$$$'!W94+'$$$$$'!W171+'$$$$$'!W198 -> 2359652.5 | C33: =+'$$$$$'!V46+'$$$$$'!V70+'$$$$$'!V94+'$$$$$'!V171+'$$$$$'!V198 -> 6974.8 | D33: =+B33/C33 -> 338.31113 | E33: =+'RESUMEN CDMX'!T26+FRIGARSA!Q24+FRESCO!Q25+MEXIDELI!Q24+CANBELT!Q8 -> 1722
A34: Bajo Cero | B34: =+'$$$$$'!W139 -> 1401514.9 | C34: =+'$$$$$'!V139 -> 4955.16 | D34: =+B34/C34 -> 282.83949 | E34: =+'VULPES PAPAS'!Q35 -> 1424.08
A35: Frjalisco | B35: =+'$$$$$'!W112 -> 1084783.8 | C35: =+'$$$$$'!V112 -> 3930 | D35: =+B35/C35 -> 276.02642 | E35: =+FRIJALISCO!T28 -> 2227
A36: Alfrimex | D36: =+B36/C36 -> #DIV/0!
A37: Vulpes | B37: =+'$$$$$'!W167 -> 649082.81 | C37: =+'$$$$$'!V167 -> 2433.07 | D37: =+B37/C37 -> 266.77523
A38: Importe Total | B38: =SUM(B32:B37) -> 6406593.4 | C38: =SUM(C32:C37) -> 21168.28 | E38: =SUM(E32:E37) -> 8137.83
B40: ABRIL . 2026
A41: Cliente / Bodega | B41: Valo invent | C41: Cajas invent | D41: costo prom | E41: vta cajas mes | G41: Llegadas | H41: Ventas estimadas | I41: Inv actual + llegadas | J41: Inv - ventas estimadas
A42: Abastos logicos | B42: =+'$$$$$'!Y22 -> 869367.52 | C42: =+'$$$$$'!X22 -> 3176.25 | D42: =+B42/C42 -> 273.70878 | E42: =+CANCÚN!Y26 -> 2058 | G42: =+CANCÚN!BX24+CANCÚN!BY24 -> 4644 | H42: =+CANCÚN!BR24 -> 2284.0625 | I42: =+G42+C42 -> 7820.25 | J42: =+I42-H42 -> 5536.1875 | K42: =+J42/H42 -> 2.4238336
A43: CDMX: Arcosa | Fresco | Frigarsa | Canbelt | B43: =+'$$$$$'!Y46+'$$$$$'!Y70+'$$$$$'!Y94+'$$$$$'!Y171+'$$$$$'!Y198 -> 2102810.1 | C43: =+'$$$$$'!X46+'$$$$$'!X70+'$$$$$'!X94+'$$$$$'!X171+'$$$$$'!X198 -> 6095.8 | D43: =+B43/C43 -> 344.96048 | E43: =+FRIGARSA!V24+FRESCO!BO25+MEXIDELI!V24+CANBELT!V8 -> 1756 | G43: =+'RESUMEN CDMX'!AI26 -> 1476 | H43: 1200 | I43: =+G43+C43 -> 7571.8 | J43: =+I43-H43 -> 6371.8 | K43: =+J43/H43 -> 5.3098333
...

Sheet $$$$$
C2: ULTIMO COSTO 2025 | D2: COSTO ENE | E2: COSTO FEB. | F2: COSTO MAR | G2: COSTO ABR | H2: COSTO MAY | I2: COSTO JUN | J2: COSTO JUL | K2: COSTO AGO | L2: COSTO SEP | M2: COSTO OCT | N2: COSTO NOV | O2: COSTO DIC | P2: COSTO PROMEDIO | R2: INV ENERO | S2: COSTO TOTAL | T2: INV FEBRERO | U2: COSTO TOTAL | V2: INV MARZO | W2: COSTO TOTAL | X2: INV ABRIL | Y2: COSTO TOTAL | Z2: INV MAYO | AA2: COSTO TOTAL | AB2: INV JUNIO | AC2: COSTO TOTAL | AD2: INV JULIO | AE2: COSTO TOTAL | AF2: INV AGOSTO | AG2: COSTO TOTAL | AH2: INV SEPTIEMBRE | AI2: COSTO TOTAL | AJ2: INV OCTUBRE | AK2: COSTO TOTAL | AL2: INV NOVIEMBRE | AM2: COSTO TOTAL | AN2: INV DICIEMBRE | AO2: COSTO TOTAL | AP2: INV DICIEMBRE | AQ2: COSTO TOTAL
A3: ALMACEN ABASTOS LOGICOS (CANCÚN)
A4: CÓDIGO | B4: DESCRIPCIÓN
A5: 804104 | B5: TRIANGLE HASHBROW 63G/40PZ BAG APPROX) 4 X 2.5KG | C5: 404.86 | D5: =+C5 -> 404.86 | E5: =+D5 -> 404.86 | F5: =+E5 -> 404.86 | G5: =+F5 -> 404.86 | H5: =+G5 -> 404.86 | I5: =+H5 -> 404.86 | J5: =+I5 -> 404.86 | K5: =+J5 -> 404.86 | ... O5: =+N5 -> 404.86 | P5: =+AVERAGE(D5:O5) -> 404.86 | R5: =+CANCÚN!K3 -> 493.25 | S5: =+R5*D5 -> 199697.2 | T5: =+CANCÚN!P3 -> 259 | U5: =+T5*E5 -> 104858.74 | V5: =+CANCÚN!U3 -> 103.25 | W5: =+V5*F5 -> 41801.795 | X5: =+CANCÚN!Z3 -> 59.25 | Y5: =+X5*G5 -> 23987.955 | Z5: =+CANCÚN!AE3 -> 35 | AA5: =+Z5*H5 -> 14170.1
A6: 805567 | B6: HASBROWNS ROUNDS - FRYER 4X2500G | C6: 406.79 | D6: =+C6 -> 406.79 | E6: =+D6 -> 406.79 | F6: =+E6 -> 406.79 | G6: =+F6 -> 406.79 | H6: =+G6 -> 406.79 | I6: =+H6 -> 406.79 | J6: =+I6 -> 406.79 | K6: =+J6 -> 406.79 | ... O6: =+N6 -> 406.79 | P6: =+AVERAGE(D6:O6) -> 406.79 | R6: =+CANCÚN!K4 -> 743.5 | S6: =+R6*D6 -> 302448.36 | T6: =+CANCÚN!P4 -> 743.5 | U6: =+T6*E6 -> 302448.36 | V6: =+CANCÚN!U4 -> 466.25 | W6: =+V6*F6 -> 189665.84 | X6: =+CANCÚN!Z4 -> 148.25 | Y6: =+X6*G6 -> 60306.618 | Z6: =+CANCÚN!AE4 -> 111.25 | AA6: =+Z6*H6 -> 45255.388
A7: 803528 | B7: Aviko H Pommes Frites 11mm 7/16 4x2500g | C7: 264.35 | D7: =+C7 -> 264.35 | E7: =+D7 -> 264.35 | F7: =+E7 -> 264.35 | G7: =+F7 -> 264.35 | H7: =+G7 -> 264.35 | I7: =+H7 -> 264.35 | J7: =+I7 -> 264.35 | K7: =+J7 -> 264.35 | ... O7: =+N7 -> 264.35 | P7: =+AVERAGE(D7:O7) -> 264.35 | R7: =+CANCÚN!K5 -> 0 | S7: =+R7*D7 -> 0 | T7: =+CANCÚN!P5 -> 0 | U7: =+T7*E7 -> 0 | V7: =+CANCÚN!U5 -> 0 | W7: =+V7*F7 -> 0 | X7: =+CANCÚN!Z5 -> 0 | Y7: =+X7*G7 -> 0 | Z7: =+CANCÚN!AE5 -> 0 | AA7: =+Z7*H7 -> 0
A8: 806685 | B8: AVIKO H PREM.CRUNCH SHOESTRING 7MM 4X2270G | C8: 360.49 | D8: =+C8 -> 360.49 | E8: =+D8 -> 360.49 | F8: =+E8 -> 360.49 | G8: =+F8 -> 360.49 | H8: =+G8 -> 360.49 | I8: =+H8 -> 360.49 | J8: =+I8 -> 360.49 | K8: =+J8 -> 360.49 | ... O8: =+N8 -> 360.49 | P8: =+AVERAGE(D8:O8) -> 360.49 | R8: =+CANCÚN!K6 -> 0.25 | S8: =+R8*D8 -> 90.1225 | T8: =+CANCÚN!P6 -> 0 | U8: =+T8*E8 -> 0 | V8: =+CANCÚN!U6 -> 0 | W8: =+V8*F8 -> 0 | X8: =+CANCÚN!Z6 -> 0 | Y8: =+X8*G8 -> 0 | Z8: =+CANCÚN!AE6 -> 0 | AA8: =+Z8*H8 -> 0
D9: =+C9 -> 0 | E9: =+D9 -> 0 | F9: =+E9 -> 0 | G9: =+F9 -> 0 | H9: =+G9 -> 0 | I9: =+H9 -> 0 | J9: =+I9 -> 0 | K9: =+J9 -> 0 | ... O9: =+N9 -> 0 | P9: =+AVERAGE(D9:O9) -> 0 | S9: =+R9*D9 -> 0 | U9: =+T9*E9 -> 0 | W9: =+V9*F9 -> 0 | Y9: =+X9*G9 -> 0 | AA9: =+Z9*H9 -> 0
D10: =+C10 -> 0 | E10: =+D10 -> 0 | F10: =+E10 -> 0 | G10: =+F10 -> 0 | H10: =+G10 -> 0 | I10: =+H10 -> 0 | J10: =+I10 -> 0 | K10: =+J10 -> 0 | ... O10: =+N10 -> 0 | P10: =+AVERAGE(D10:O10) -> 0 | S10: =+R10*D10 -> 0 | U10: =+T10*E10 -> 0 | W10: =+V10*F10 -> 0 | Y10: =+X10*G10 -> 0 | AA10: =+Z10*H10 -> 0
D11: =+C11 -> 0 | E11: =+D11 -> 0 | F11: =+E11 -> 0 | G11: =+F11 -> 0 | H11: =+G11 -> 0 | I11: =+H11 -> 0 | J11: =+I11 -> 0 | K11: =+J11 -> 0 | ... O11: =+N11 -> 0 | P11: =+AVERAGE(D11:O11) -> 0 | S11: =+R11*D11 -> 0 | U11: =+T11*E11 -> 0 | W11: =+V11*F11 -> 0 | Y11: =+X11*G11 -> 0 | AA11: =+Z11*H11 -> 0
A12: 105632 | B12: 10 MM NATURAL | C12: 280.75 | D12: 258.94 | E12: =+D12 -> 258.94 | F12: =+E12 -> 258.94 | G12: =+F12 -> 258.94 | H12: =+G12 -> 258.94 | I12: =+H12 -> 258.94 | J12: =+I12 -> 258.94 | K12: =+J12 -> 258.94 | L12: =+K12 -> 258.94 | ... O12: =+N12 -> 258.94 | P12: =+AVERAGE(D12:O12) -> 258.94 | R12: =+CANCÚN!K13 -> 3287.75 | S12: =+R12*D12 -> 851329.98 | T12: =+CANCÚN!P13 -> 2368 | U12: =+T12*E12 -> 613169.92 | V12: =+CANCÚN!U13 -> 746.75 | W12: =+V12*F12 -> 193363.45 | X12: =+CANCÚN!Z13 -> 0 | Y12: =+X12*G12 -> 0 | Z12: =+CANCÚN!AE13 -> 0 | AA12: =+Z12*H12 -> 0
A13: 102341 | B13: 10 MM CON COBERTURA | D13: 290.71 | E13: =+D13 -> 290.71 | F13: =+E13 -> 290.71 | G13: =+F13 -> 290.71 | H13: =+G13 -> 290.71 | I13: =+H13 -> 290.71 | J13: =+I13 -> 290.71 | K13: =+J13 -> 290.71 | L13: =+K13 -> 290.71 | ... O13: =+N13 -> 290.71 | P13: =+AVERAGE(D13:O13) -> 290.71 | R13: =+CANCÚN!K15 -> 2144.5 | S13: =+R13*D13 -> 623427.59 | T13: =+CANCÚN!P15 -> 1630.5 | U13: =+T13*E13 -> 474002.65 | V13: =+CANCÚN!U15 -> 1020.25 | W13: =+V13*F13 -> 296596.88 | X13: =+CANCÚN!Z15 -> 576.25 | Y13: =+X13*G13 -> 167521.64 | Z13: =+CANCÚN!AE15 -> 550.25 | AA13: =+Z13*H13 -> 159963.18
A14: 102310 | B14: 7 MM CON COBERTURA | C14: 361.11 | D14: =+C14 -> 361.11 | E14: =+D14 -> 361.11 | F14: =+E14 -> 361.11 | G14: 282.79 | H14: =+G14 -> 282.79 | I14: =+H14 -> 282.79 | J14: =+I14 -> 282.79 | K14: =+J14 -> 282.79 | L14: =+K14 -> 282.79 | M14: =+L14 -> 282.79 | N14: =+M14 -> 282.79 | O14: =+N14 -> 282.79 | P14: =+AVERAGE(D14:O14) -> 302.37 | R14: =+CANCÚN!K16 -> 99 | S14: =+R14*D14 -> 35749.89 | T14: =+CANCÚN!P16 -> 66.5 | U14: =+T14*E14 -> 24013.815 | V14: =+CANCÚN!U16 -> 38.75 | W14: =+V14*F14 -> 13993.013 | X14: =+CANCÚN!Z16 -> 134.75 | Y14: =+X14*G14 -> 38105.952 | Z14: =+CANCÚN!AE16 -> 123.75 | AA14: =+Z14*H14 -> 34995.263
A15: 102211 | B15: 7 MM NATURAL | C15: 360.56 | D15: =+C15 -> 360.56 | E15: =+D15 -> 360.56 | F15: =+E15 -> 360.56 | G15: =+F15 -> 360.56 | H15: =+G15 -> 360.56 | I15: =+H15 -> 360.56 | J15: =+I15 -> 360.56 | K15: =+J15 -> 360.56 | ... O15: =+N15 -> 360.56 | P15: =+AVERAGE(D15:O15) -> 360.56 | R15: =+CANCÚN!K17 -> 0 | S15: =+R15*D15 -> 0 | T15: =+CANCÚN!P17 -> 0 | U15: =+T15*E15 -> 0 | V15: =+CANCÚN!U17 -> 0 | W15: =+V15*F15 -> 0 | X15: =+CANCÚN!Z17 -> 0 | Y15: =+X15*G15 -> 0 | Z15: =+CANCÚN!AE17 -> 0 | AA15: =+Z15*H15 -> 0
A16: 104215 | B16: 10 MM CON COBERTURA Y CASCARA | C16: 393.15 | D16: 393.15 | E16: =+D16 -> 393.15 | F16: =+E16 -> 393.15 | G16: =+F16 -> 393.15 | H16: =+G16 -> 393.15 | I16: =+H16 -> 393.15 | J16: =+I16 -> 393.15 | K16: =+J16 -> 393.15 | L16: =+K16 -> 393.15 | ... O16: =+N16 -> 393.15 | P16: =+AVERAGE(D16:O16) -> 393.15 | R16: =+CANCÚN!K18 -> 0 | S16: =+R16*D16 -> 0 | T16: =+CANCÚN!P18 -> 0 | U16: =+T16*E16 -> 0 | V16: =+CANCÚN!U18 -> 0 | W16: =+V16*F16 -> 0 | X16: =+CANCÚN!Z18 -> 0 | Y16: =+X16*G16 -> 0 | Z16: =+CANCÚN!AE18 -> 0 | AA16: =+Z16*H16 -> 0
A17: 114054 | B17: GAJOS SAZONADOS | C17: 370.2 | D17: =+C17 -> 370.2 | E17: =+D17 -> 370.2 | F17: =+E17 -> 370.2 | G17: =+F17 -> 370.2 | H17: =+G17 -> 370.2 | I17: =+H17 -> 370.2 | J17: =+I17 -> 370.2 | K17: =+J17 -> 370.2 | ... O17: =+N17 -> 370.2 | P17: =+AVERAGE(D17:O17) -> 370.2 | R17: =+CANCÚN!K19 -> 486.25 | S17: =+R17*D17 -> 180009.75 | T17: =+CANCÚN!P19 -> 447.75 | U17: =+T17*E17 -> 165757.05 | V17: =+CANCÚN!U19 -> 420.75 | W17: =+V17*F17 -> 155761.65 | X17: =+CANCÚN!Z19 -> 391.5 | Y17: =+X17*G17 -> 144933.3 | Z17: =+CANCÚN!AE19 -> 384.5 | AA17: =+Z17*H17 -> 142341.9
A18: 102419 | B18: ONDULADA | C18: 311.91 | D18: 257.12 | E18: =+D18 -> 257.12 | F18: =+E18 -> 257.12 | G18: 234.64 | H18: =+G18 -> 234.64 | I18: =+H18 -> 234.64 | J18: =+I18 -> 234.64 | K18: =+J18 -> 234.64 | L18: =+K18 -> 234.64 | M18: =+L18 -> 234.64 | N18: =+M18 -> 234.64 | O18: =+N18 -> 234.64 | P18: =+AVERAGE(D18:O18) -> 240.26 | R18: =+CANCÚN!K20 -> 149 | S18: =+R18*D18 -> 38310.88 | T18: =+CANCÚN!P20 -> 114.75 | U18: =+T18*E18 -> 29504.52 | V18: =+CANCÚN!U20 -> 79.25 | W18: =+V18*F18 -> 20376.76 | X18: =+CANCÚN!Z20 -> 182.25 | Y18: =+X18*G18 -> 42763.14 | Z18: =+CANCÚN!AE20 -> 166.5 | AA18: =+Z18*H18 -> 39067.56
A19: 1000440 | B19: 3/8 VIMA FOODS | C19: 330 | D19: =+C19 -> 330 | E19: =+D19 -> 330 | F19: =+E19 -> 330 | G19: =+F19 -> 330 | H19: =+G19 -> 330 | I19: =+H19 -> 330 | J19: =+I19 -> 330 | K19: =+J19 -> 330 | ... O19: =+N19 -> 330 | P19: =+AVERAGE(D19:O19) -> 330 | R19: =+CANCÚN!K21 -> 3.25 | S19: =+R19*D19 -> 1072.5 | T19: =+CANCÚN!P21 -> 0 | U19: =+T19*E19 -> 0 | V19: =+CANCÚN!U21 -> 0 | W19: =+V19*F19 -> 0 | X19: =+CANCÚN!Z21 -> 0 | Y19: =+X19*G19 -> 0 | Z19: =+CANCÚN!AE21 -> 0 | AA19: =+Z19*H19 -> 0
A20: 102013 | B20: 10 MM NATURAL | C20: 318.12 | D20: =+C20 -> 318.12 | E20: =+D20 -> 318.12 | F20: =+E20 -> 318.12 | G20: 232.63 | H20: =+G20 -> 232.63 | I20: =+H20 -> 232.63 | J20: =+I20 -> 232.63 | K20: =+J20 -> 232.63 | L20: =+K20 -> 232.63 | M20: =+L20 -> 232.63 | N20: =+M20 -> 232.63 | O20: =+N20 -> 232.63 | P20: =+AVERAGE(D20:O20) -> 254.0025 | R20: =+CANCÚN!K14 -> 0 | S20: =+R20*D20 -> 0 | T20: =+CANCÚN!P14 -> 0 | U20: =+T20*E20 -> 0 | V20: =+CANCÚN!U14 -> 0 | W20: =+V20*F20 -> 0 | X20: =+CANCÚN!Z14 -> 1684 | Y20: =+X20*G20 -> 391748.92 | Z20: =+CANCÚN!AE14 -> 1320.75 | AA20: =+Z20*H20 -> 307246.07
D21: =+C21 -> 0 | E21: =+D21 -> 0 | F21: =+E21 -> 0 | G21: =+F21 -> 0 | H21: =+G21 -> 0 | I21: =+H21 -> 0 | J21: =+I21 -> 0 | K21: =+J21 -> 0 | ... O21: =+N21 -> 0 | P21: =+AVERAGE(D21:O21) -> 0 | S21: =+R21*D21 -> 0 | W21: =+V21*F21 -> 0 | AA21: =+Z21*H21 -> 0
A22: TOTAL CANCUN | R22: =+SUM(R5:R21) -> 7406.75 | S22: =+SUM(S5:S21) -> 2232136.3 | T22: =+SUM(T5:T21) -> 5630 | U22: =+SUM(U5:U21) -> 1713755.1 | V22: =+SUM(V5:V21) -> 2875.25 | W22: =+SUM(W5:W21) -> 911559.38 | X22: =+SUM(X5:X21) -> 3176.25 | Y22: =+SUM(Y5:Y21) -> 869367.52 | ... AA22: =+SUM(AA5:AA21) -> 743039.46
A24: ALMACEN ARCOSA
A25: 806685 | B25: AVIKO H PREM.CRUNCH SHOESTRING 7MM 4X2270G | C25: 344.32 | D25: 305.47 | E25: 297.01 | F25: 318.2 | G25: =+F25 -> 318.2 | H25: =+G25 -> 318.2 | I25: =+H25 -> 318.2 | J25: =+I25 -> 318.2 | K25: =+J25 -> 318.2 | L25: =+K25 -> 318.2 | M25: =+L25 -> 318.2 | N25: =+M25 -> 318.2 | O25: =+N25 -> 318.2 | P25: =+AVERAGE(D25:O25) -> 315.37333 | R25: =+'RESUMEN CDMX'!K4 -> 0 | S25: =+R25*D25 -> 0 | T25: =+'RESUMEN CDMX'!P4 -> 0 | U25: =+T25*E25 -> 0 | V25: 0 | W25: =+V25*F25 -> 0 | X25: 0 | Y25: =+X25*H25 -> 0
A26: 806939 | B26: AVIKO CRINKLE CUT 12MM 4 X 2.5 KG | C26: 326.49 | D26: =+C26 -> 326.49 | E26: 287.31 | F26: 308.53 | G26: =+F26 -> 308.53 | H26: =+G26 -> 308.53 | I26: =+H26 -> 308.53 | J26: =+I26 -> 308.53 | K26: =+J26 -> 308.53 | L26: =+K26 -> 308.53 | M26: =+L26 -> 308.53 | N26: =+M26 -> 308.53 | O26: =+N26 -> 308.53 | P26: =+AVERAGE(D26:O26) -> 308.25833 | R26: =+'RESUMEN CDMX'!K5 -> 0 | S26: =+R26*D26 -> 0 | T26: =+'RESUMEN CDMX'!P5 -> 0 | U26: =+T26*E26 -> 0 | V26: 0 | W26: =+V26*F26 -> 0 | X26: 0 | Y26: =+X26*H26 -> 0
A27: 806694 | B27: AVIKO SUPER CRUNCH 9.5mm 3/8 4x2500g | C27: 382.98 | D27: =+C27 -> 382.98 | E27: 325.08 | F27: 366.07 | G27: =+F27 -> 366.07 | H27: =+G27 -> 366.07 | I27: =+H27 -> 366.07 | J27: =+I27 -> 366.07 | K27: =+J27 -> 366.07 | L27: =+K27 -> 366.07 | M27: =+L27 -> 366.07 | N27: =+M27 -> 366.07 | O27: =+N27 -> 366.07 | P27: =+AVERAGE(D27:O27) -> 364.06333 | R27: =+'RESUMEN CDMX'!K6 -> 0 | S27: =+R27*D27 -> 0 | T27: =+'RESUMEN CDMX'!P6 -> 0 | U27: =+T27*E27 -> 0 | V27: 0 | W27: =+V27*F27 -> 0 | X27: 0 | Y27: =+X27*H27 -> 0
A28: 804104 | B28: HASHBROWN TRIANG | C28: 369.36 | D28: =+C28 -> 369.36 | E28: =+D28 -> 369.36 | F28: =+E28 -> 369.36 | G28: =+F28 -> 369.36 | H28: =+G28 -> 369.36 | I28: =+H28 -> 369.36 | J28: =+I28 -> 369.36 | K28: =+J28 -> 369.36 | ... O28: =+N28 -> 369.36 | P28: =+AVERAGE(D28:O28) -> 369.36 | R28: =+'RESUMEN CDMX'!K7 -> 0 | S28: =+R28*D28 -> 0 | T28: =+'RESUMEN CDMX'!P7 -> 0 | U28: =+T28*E28 -> 0 | V28: 0 | W28: =+V28*F28 -> 0 | X28: 0 | Y28: =+X28*H28 -> 0
A29: 806686 | B29: AVIKO H PREM CRUNCH 9.5 mm 3/8 4x2270g | C29: 320.48 | D29: =+C29 -> 320.48 | E29: 297.01 | F29: =+E29 -> 297.01 | G29: =+F29 -> 297.01 | H29: =+G29 -> 297.01 | I29: =+H29 -> 297.01 | J29: =+I29 -> 297.01 | K29: =+J29 -> 297.01 | L29: =+K29 -> 297.01 | M29: =+L29 -> 297.01 | ... O29: =+N29 -> 297.01 | P29: =+AVERAGE(D29:O29) -> 298.96583 | R29: =+'RESUMEN CDMX'!K8 -> 161 | S29: =+R29*D29 -> 51597.28 | T29: =+'RESUMEN CDMX'!P8 -> 112 | U29: =+T29*E29 -> 33265.12 | V29: 0 | W29: =+V29*F29 -> 0 | X29: 0 | Y29: =+X29*H29 -> 0
A30: 804109 | B30: AVIKO SHOESTRING 5x2500g | C30: 424.92 | D30: =+C30 -> 424.92 | E30: 361.2 | F30: 370.16 | G30: =+F30 -> 370.16 | H30: =+G30 -> 370.16 | I30: =+H30 -> 370.16 | J30: =+I30 -> 370.16 | K30: =+J30 -> 370.16 | L30: =+K30 -> 370.16 | M30: =+L30 -> 370.16 | N30: =+M30 -> 370.16 | O30: =+N30 -> 370.16 | P30: =+AVERAGE(D30:O30) -> 373.97667 | R30: =+'RESUMEN CDMX'!K9 -> 1 | S30: =+R30*D30 -> 424.92 | T30: =+'RESUMEN CDMX'!P9 -> 1 | U30: =+T30*E30 -> 361.2 | V30: 0 | W30: =+V30*F30 -> 0 | X30: 0 | Y30: =+X30*H30 -> 0
A31: 806980 | B31: AVIKO SPICY JACKET WEDGES 4x2500g | C31: 371.47 | D31: =+C31 -> 371.47 | E31: 314.14 | F31: =+E31 -> 314.14 | G31: =+F31 -> 314.14 | H31: =+G31 -> 314.14 | I31: =+H31 -> 314.14 | J31: =+I31 -> 314.14 | K31: =+J31 -> 314.14 | L31: =+K31 -> 314.14 | M31: =+L31 -> 314.14 | ... O31: =+N31 -> 314.14 | P31: =+AVERAGE(D31:O31) -> 318.9175 | R31: =+'RESUMEN CDMX'!K10 -> 25 | S31: =+R31*D31 -> 9286.75 | T31: =+'RESUMEN CDMX'!P10 -> 25 | U31: =+T31*E31 -> 7853.5 | V31: 0 | W31: =+V31*F31 -> 0 | X31: 0 | Y31: =+X31*H31 -> 0
A32: 806982 | B32: AROS DE CEBOLLA 1X1000g | C32: 346.77 | D32: =+C32 -> 346.77 | E32: =+D32 -> 346.77 | F32: 337.55 | G32: =+F32 -> 337.55 | H32: =+G32 -> 337.55 | I32: =+H32 -> 337.55 | J32: =+I32 -> 337.55 | K32: =+J32 -> 337.55 | L32: =+K32 -> 337.55 | M32: =+L32 -> 337.55 | N32: =+M32 -> 337.55 | O32: =+N32 -> 337.55 | P32: =+AVERAGE(D32:O32) -> 339.08667 | R32: =+'RESUMEN CDMX'!K11 -> 50 | S32: =+R32*D32 -> 17338.5 | T32: =+'RESUMEN CDMX'!P11 -> 50 | U32: =+T32*E32 -> 17338.5 | V32: 0 | W32: =+V32*F32 -> 0 | X32: 0 | Y32: =+X32*H32 -> 0
A33: 260612 | B33: CASTEL STRAIGHT CUT FRIES 4X2500g | C33: 298.86 | D33: =+C33 -> 298.86 | E33: =+D33 -> 298.86 | F33: =+E33 -> 298.86 | G33: =+F33 -> 298.86 | H33: =+G33 -> 298.86 | I33: =+H33 -> 298.86 | J33: =+I33 -> 298.86 | K33: =+J33 -> 298.86 | ... O33: =+N33 -> 298.86 | P33: =+AVERAGE(D33:O33) -> 298.86 | R33: =+'RESUMEN CDMX'!K12 -> 66 | S33: =+R33*D33 -> 19724.76 | T33: =+'RESUMEN CDMX'!P12 -> 66 | U33: =+T33*E33 -> 19724.76 | V33: 0 | W33: =+V33*F33 -> 0 | X33: 0 | Y33: =+X33*H33 -> 0
A34: 804661 | B34: AVIKO STEAK FRIES 4X2500G 4X5.5 LBS | C34: 329.94 | D34: =+C34 -> 329.94 | E34: =+D34 -> 329.94 | F34: =+E34 -> 329.94 | G34: =+F34 -> 329.94 | H34: =+G34 -> 329.94 | I34: =+H34 -> 329.94 | J34: =+I34 -> 329.94 | K34: =+J34 -> 329.94 | ... O34: =+N34 -> 329.94 | P34: =+AVERAGE(D34:O34) -> 329.94 | R34: =+'RESUMEN CDMX'!K13 -> 0 | S34: =+R34*D34 -> 0 | T34: =+'RESUMEN CDMX'!P13 -> 0 | U34: =+T34*E34 -> 0 | V34: 0 | W34: =+V34*F34 -> 0 | X34: 0 | Y34: =+X34*H34 -> 0
A35: 806702 | B35: AVIKO H SUPER CRUNCH 15mm 6x2500g | C35: 554.39 | D35: 432.95 | E35: =+D35 -> 432.95 | F35: =+E35 -> 432.95 | G35: =+F35 -> 432.95 | H35: =+G35 -> 432.95 | I35: =+H35 -> 432.95 | J35: =+I35 -> 432.95 | K35: =+J35 -> 432.95 | L35: =+K35 -> 432.95 | ... O35: =+N35 -> 432.95 | P35: =+AVERAGE(D35:O35) -> 432.95 | R35: =+'RESUMEN CDMX'!K14 -> 0 | S35: =+R35*D35 -> 0 | T35: =+'RESUMEN CDMX'!P14 -> 0 | U35: =+T35*E35 -> 0 | V35: 0 | W35: =+V35*F35 -> 0 | X35: 0 | Y35: =+X35*H35 -> 0
A36: 807769 | B36: PAPAS FRITAS CORTE REG 10 X 1000G | C36: 346.43 | D36: =+C36 -> 346.43 | E36: =+D36 -> 346.43 | F36: =+E36 -> 346.43 | G36: =+F36 -> 346.43 | H36: =+G36 -> 346.43 | I36: =+H36 -> 346.43 | J36: =+I36 -> 346.43 | K36: =+J36 -> 346.43 | ... O36: =+N36 -> 346.43 | P36: =+AVERAGE(D36:O36) -> 346.43 | R36: =+'RESUMEN CDMX'!K15 -> 0 | S36: =+R36*D36 -> 0 | T36: =+'RESUMEN CDMX'!P15 -> 0 | U36: =+T36*E36 -> 0 | V36: 0 | W36: =+V36*F36 -> 0 | X36: 0 | Y36: =+X36*H36 -> 0
A37: 807329 | B37: AVIKO ORIGINAL 20X450G | C37: 356.34 | D37: =+C37 -> 356.34 | E37: =+D37 -> 356.34 | F37: =+E37 -> 356.34 | G37: =+F37 -> 356.34 | H37: =+G37 -> 356.34 | I37: =+H37 -> 356.34 | J37: =+I37 -> 356.34 | K37: =+J37 -> 356.34 | ... O37: =+N37 -> 356.34 | P37: =+AVERAGE(D37:O37) -> 356.34 | R37: =+'RESUMEN CDMX'!K16 -> 0 | S37: =+R37*D37 -> 0 | T37: =+'RESUMEN CDMX'!P16 -> 0 | U37: =+T37*E37 -> 0 | V37: 0 | W37: =+V37*F37 -> 0 | X37: 0 | Y37: =+X37*H37 -> 0
A38: 805411 | B38: PAPAS FRITAS ZIGZAG 12/750GRS | C38: 340.91 | D38: =+C38 -> 340.91 | E38: 306.5 | F38: =+E38 -> 306.5 | G38: =+F38 -> 306.5 | H38: =+G38 -> 306.5 | I38: =+H38 -> 306.5 | J38: =+I38 -> 306.5 | K38: =+J38 -> 306.5 | L38: =+K38 -> 306.5 | M38: =+L38 -> 306.5 | ... O38: =+N38 -> 306.5 | P38: =+AVERAGE(D38:O38) -> 309.3675 | R38: =+'RESUMEN CDMX'!K17 -> 89.8 | S38: =+R38*D38 -> 30613.718 | T38: =+'RESUMEN CDMX'!P17 -> 55.8 | U38: =+T38*E38 -> 17102.7 | V38: 0 | W38: =+V38*F38 -> 0 | X38: 0 | Y38: =+X38*H38 -> 0
A39: 807679 | B39: AVIKO SPICY WEDGES 20X500G | C39: 388.31 | D39: =+C39 -> 388.31 | E39: 363.68 | F39: 386.98 | G39: =+F39 -> 386.98 | H39: =+G39 -> 386.98 | I39: =+H39 -> 386.98 | J39: =+I39 -> 386.98 | K39: =+J39 -> 386.98 | L39: =+K39 -> 386.98 | M39: =+L39 -> 386.98 | N39: =+M39 -> 386.98 | O39: =+N39 -> 386.98 | P39: =+AVERAGE(D39:O39) -> 385.14917 | R39: =+'RESUMEN CDMX'!K18 -> 393 | S39: =+R39*D39 -> 152605.83 | T39: =+'RESUMEN CDMX'!P18 -> 322 | U39: =+T39*E39 -> 117104.96 | V39: 0 | W39: =+V39*F39 -> 0 | X39: 0 | Y39: =+X39*H39 -> 0
A40: 805168 | B40: AVIKO AROS DE CEBOLLA PREFRITOS 25/400g | C40: 608.68 | D40: =+C40 -> 608.68 | E40: =+D40 -> 608.68 | F40: =+E40 -> 608.68 | G40: =+F40 -> 608.68 | H40: =+G40 -> 608.68 | I40: =+H40 -> 608.68 | J40: =+I40 -> 608.68 | K40: =+J40 -> 608.68 | ... O40: =+N40 -> 608.68 | P40: =+AVERAGE(D40:O40) -> 608.68 | R40: =+'RESUMEN CDMX'!K19 -> 277 | S40: =+R40*D40 -> 168604.36 | T40: =+'RESUMEN CDMX'!P19 -> 200 | U40: =+T40*E40 -> 121736 | V40: 0 | W40: =+V40*F40 -> 0 | X40: 0 | Y40: =+X40*H40 -> 0
A41: 807363 | B41: Aviko H Super Crunch 14x600g | C41: 357.28 | D41: =+C41 -> 357.28 | E41: =+D41 -> 357.28 | F41: =+E41 -> 357.28 | G41: =+F41 -> 357.28 | H41: =+G41 -> 357.28 | I41: =+H41 -> 357.28 | J41: =+I41 -> 357.28 | K41: =+J41 -> 357.28 | ... O41: =+N41 -> 357.28 | P41: =+AVERAGE(D41:O41) -> 357.28 | R41: =+'RESUMEN CDMX'!K20 -> 26 | S41: =+R41*D41 -> 9289.28 | T41: =+'RESUMEN CDMX'!P20 -> 17 | U41: =+T41*E41 -> 6073.76 | V41: 0 | W41: =+V41*F41 -> 0 | X41: 0 | Y41: =+X41*H41 -> 0
A42: 809529 | B42: Aviko SC Airfr. PommesFrites 10x750 | C42: 353.79 | D42: =+C42 -> 353.79 | E42: =+D42 -> 353.79 | F42: =+E42 -> 353.79 | G42: =+F42 -> 353.79 | H42: =+G42 -> 353.79 | I42: =+H42 -> 353.79 | J42: =+I42 -> 353.79 | K42: =+J42 -> 353.79 | ... O42: =+N42 -> 353.79 | P42: =+AVERAGE(D42:O42) -> 353.79 | R42: =+'RESUMEN CDMX'!K21 -> 397 | S42: =+R42*D42 -> 140454.63 | T42: =+'RESUMEN CDMX'!P21 -> 397 | U42: =+T42*E42 -> 140454.63 | V42: 0 | W42: =+V42*F42 -> 0 | X42: 0 | Y42: =+X42*H42 -> 0
...

Sheet Resumen Ventas
A1: VENTAS x ALMACÉN | D1: DICIEMBRE | E1: ENERO | F1: FEBRERO | G1: MARZO | H1: ABRIL | I1: MAYO | J1: JUNIO | K1: JULIO | M1: PROMEDIO | O1: %
A2: ABASTOS LOGICOS | B2: CÓDIGO | C2: DESCRIPCIÓN | I2: =+CANCÚN!#REF! -> #REF! | J2: =+CANCÚN!#REF! -> #REF! | K2: =+CANCÚN!#REF! -> #REF!
B3: 802142 | C3: STRAIGHT CUT 3/8 4X2500 | D3: 0.75 | E3: =+CANCÚN!#REF! -> #REF! | F3: =+CANCÚN!#REF! -> #REF! | G3: =+CANCÚN!#REF! -> #REF! | H3: =+CANCÚN!#REF! -> #REF! | I3: =+CANCÚN!#REF! -> #REF! | J3: =+CANCÚN!#REF! -> #REF! | K3: =+CANCÚN!#REF! -> #REF! | M3: =+AVERAGE(J3,I3,K3) -> #REF! | O3: =+M3/$M$24 -> #REF!
B4: 806686 | C4: H PREMIUM CRUNCH 9.5MM 3/8 4X2500G | E4: =+CANCÚN!#REF! -> #REF! | F4: =+CANCÚN!#REF! -> #REF! | G4: =+CANCÚN!#REF! -> #REF! | H4: =+CANCÚN!#REF! -> #REF! | I4: =+CANCÚN!#REF! -> #REF! | J4: =+CANCÚN!#REF! -> #REF! | K4: =+CANCÚN!#REF! -> #REF! | M4: =+AVERAGE(J4,I4,K4) -> #REF! | O4: =+M4/$M$24 -> #REF!
B5: 806980 | C5: SPICY JACKET WEDGES 4X2500G | E5: =+CANCÚN!#REF! -> #REF! | F5: =+CANCÚN!#REF! -> #REF! | G5: =+CANCÚN!#REF! -> #REF! | H5: =+CANCÚN!#REF! -> #REF! | I5: =+CANCÚN!#REF! -> #REF! | J5: =+CANCÚN!#REF! -> #REF! | K5: =+CANCÚN!#REF! -> #REF! | M5: =+AVERAGE(J5,I5,K5) -> #REF! | O5: =+M5/$M$24 -> #REF!
B6: 804104 | C6: TRIANGLE HASHBROW 63G/40PZ BAG APPROX) 4 X 2.5KG | D6: 147 | E6: =+CANCÚN!J3 -> 56.25 | F6: =+CANCÚN!#REF! -> #REF! | G6: =+CANCÚN!#REF! -> #REF! | H6: =+CANCÚN!#REF! -> #REF! | I6: =+CANCÚN!#REF! -> #REF! | J6: =+CANCÚN!#REF! -> #REF! | K6: =+CANCÚN!#REF! -> #REF! | M6: =+AVERAGE(J6,I6,K6) -> #REF! | O6: =+M6/$M$24 -> #REF!
B7: 805567 | C7: HASBROWNS ROUNDS - FRYER 4X2500G | D7: 1 | E7: =+CANCÚN!J4 -> 0 | F7: =+CANCÚN!#REF! -> #REF! | G7: =+CANCÚN!#REF! -> #REF! | H7: =+CANCÚN!#REF! -> #REF! | I7: =+CANCÚN!#REF! -> #REF! | J7: =+CANCÚN!#REF! -> #REF! | K7: =+CANCÚN!#REF! -> #REF! | M7: =+AVERAGE(J7,I7,K7) -> #REF! | O7: =+M7/$M$24 -> #REF!
B8: 806982 | C8: ONION RINGS BREADED EXTRUDED (60 PZ BAG APROXX) 6X1KG | D8: 20 | E8: =+CANCÚN!#REF! -> #REF! | F8: =+CANCÚN!#REF! -> #REF! | G8: =+CANCÚN!#REF! -> #REF! | H8: =+CANCÚN!#REF! -> #REF! | I8: =+CANCÚN!#REF! -> #REF! | J8: =+CANCÚN!#REF! -> #REF! | K8: =+CANCÚN!#REF! -> #REF! | M8: =+AVERAGE(J8,I8,K8) -> #REF! | O8: =+M8/$M$24 -> #REF!
B9: 803572 | C9: MEGA WEDGES (8CUT) SKIN ON 4X2.5 KG | E9: =+CANCÚN!#REF! -> #REF! | F9: =+CANCÚN!#REF! -> #REF! | G9: =+CANCÚN!#REF! -> #REF! | H9: =+CANCÚN!#REF! -> #REF! | I9: =+CANCÚN!#REF! -> #REF! | J9: =+CANCÚN!#REF! -> #REF! | K9: =+CANCÚN!#REF! -> #REF! | M9: =+AVERAGE(J9,I9,K9) -> #REF! | O9: =+M9/$M$24 -> #REF!
B10: 260612 | C10: CASTEL STRAIGHT CUT FRIES 4X2500G 9.5MM | D10: 2 | E10: =+CANCÚN!#REF! -> #REF! | F10: =+CANCÚN!#REF! -> #REF! | G10: =+CANCÚN!#REF! -> #REF! | H10: =+CANCÚN!#REF! -> #REF! | I10: =+CANCÚN!#REF! -> #REF! | J10: =+CANCÚN!#REF! -> #REF! | K10: =+CANCÚN!#REF! -> #REF! | M10: =+AVERAGE(J10,I10,K10) -> #REF! | O10: =+M10/$M$24 -> #REF!
B11: 803528 | C11: Aviko H Pommes Frites 11mm 7/16 4x2500g | E11: =+CANCÚN!J5 -> 0 | F11: =+CANCÚN!#REF! -> #REF! | G11: =+CANCÚN!#REF! -> #REF! | H11: =+CANCÚN!#REF! -> #REF! | I11: =+CANCÚN!#REF! -> #REF! | J11: =+CANCÚN!#REF! -> #REF! | K11: =+CANCÚN!#REF! -> #REF! | M11: =+AVERAGE(J11,I11,K11) -> #REF! | O11: =+M11/$M$24 -> #REF!
B12: 806685 | C12: AVIKO H PREM.CRUNCH SHOESTRING 7MM 4X2270G | D12: 37 | E12: =+CANCÚN!J6 -> 51 | F12: =+CANCÚN!#REF! -> #REF! | G12: =+CANCÚN!#REF! -> #REF! | H12: =+CANCÚN!#REF! -> #REF! | I12: =+CANCÚN!#REF! -> #REF! | J12: =+CANCÚN!#REF! -> #REF! | K12: =+CANCÚN!#REF! -> #REF! | M12: =+AVERAGE(J12,I12,K12) -> #REF! | O12: =+M12/$M$24 -> #REF!
B13: TOTAL AVIKO | D13: =+SUM(D3:D12) -> 207.75 | E13: =+SUM(E3:E12) -> #REF! | F13: =+SUM(F3:F12) -> #REF! | G13: =+SUM(G3:G12) -> #REF! | H13: =+SUM(H3:H12) -> #REF! | I13: =+SUM(I3:I12) -> #REF! | J13: =+SUM(J3:J12) -> #REF! | K13: =+SUM(K3:K12) -> #REF! | M13: =+SUM(M3:M12) -> #REF! | O13: =SUM(O3:O12) -> #REF!
B14: 102013 | C14: straight cut 10 mm 4/2500 | D14: 1754.5 | E14: =+CANCÚN!J13 -> 1083.25 | F14: =+CANCÚN!#REF! -> #REF! | G14: =+CANCÚN!#REF! -> #REF! | H14: =+CANCÚN!#REF! -> #REF! | I14: =+CANCÚN!#REF! -> #REF! | J14: =+CANCÚN!#REF! -> #REF! | K14: =+CANCÚN!#REF! -> #REF! | M14: =+AVERAGE(J14,I14,K14) -> #REF! | O14: =+M14/$M$24 -> #REF!
B15: 102211 | C15: straight cut 7 mm 4/2500 | E15: =+CANCÚN!#REF! -> #REF! | F15: =+CANCÚN!#REF! -> #REF! | G15: =+CANCÚN!#REF! -> #REF! | H15: =+CANCÚN!#REF! -> #REF! | I15: =+CANCÚN!#REF! -> #REF! | J15: =+CANCÚN!#REF! -> #REF! | K15: =+CANCÚN!#REF! -> #REF! | M15: =+AVERAGE(J15,I15,K15) -> #REF! | O15: =+M15/$M$24 -> #REF!
B16: 102341 | C16: Coated 10mm 4/2500 | D16: 275 | E16: =+CANCÚN!J15 -> 412.25 | F16: =+CANCÚN!#REF! -> #REF! | G16: =+CANCÚN!#REF! -> #REF! | H16: =+CANCÚN!#REF! -> #REF! | I16: =+CANCÚN!#REF! -> #REF! | J16: =+CANCÚN!#REF! -> #REF! | K16: =+CANCÚN!#REF! -> #REF! | M16: =+AVERAGE(J16,I16,K16) -> #REF! | O16: =+M16/$M$24 -> #REF!
B17: 102310 | C17: Coated Julienne 7 mm 4/2500 | E17: =+CANCÚN!J16 -> 25 | F17: =+CANCÚN!#REF! -> #REF! | G17: =+CANCÚN!#REF! -> #REF! | H17: =+CANCÚN!#REF! -> #REF! | I17: =+CANCÚN!#REF! -> #REF! | J17: =+CANCÚN!#REF! -> #REF! | K17: =+CANCÚN!#REF! -> #REF! | M17: =+AVERAGE(J17,I17,K17) -> #REF! | O17: =+M17/$M$24 -> #REF!
B18: 114054 | C18: Seasonned (spicy) wedges | D18: 35.75 | E18: =+CANCÚN!J17 -> 0 | F18: =+CANCÚN!#REF! -> #REF! | G18: =+CANCÚN!#REF! -> #REF! | H18: =+CANCÚN!#REF! -> #REF! | I18: =+CANCÚN!#REF! -> #REF! | J18: =+CANCÚN!#REF! -> #REF! | K18: =+CANCÚN!#REF! -> #REF! | M18: =+AVERAGE(J18,I18,K18) -> #REF! | O18: =+M18/$M$24 -> #REF!
B19: 111435 | C19: Hashbrown triangles 14x600 | E19: =+CANCÚN!#REF! -> #REF! | F19: =+CANCÚN!#REF! -> #REF! | G19: =+CANCÚN!#REF! -> #REF! | H19: =+CANCÚN!#REF! -> #REF! | I19: =+CANCÚN!#REF! -> #REF! | J19: =+CANCÚN!#REF! -> #REF! | K19: =+CANCÚN!#REF! -> #REF! | M19: =+AVERAGE(J19,I19,K19) -> #REF! | O19: =+M19/$M$24 -> #REF!
B20: 118700 | C20: Potato with cream cheese & herbs | E20: =+CANCÚN!#REF! -> #REF! | F20: =+CANCÚN!#REF! -> #REF! | G20: =+CANCÚN!#REF! -> #REF! | H20: =+CANCÚN!#REF! -> #REF! | I20: =+CANCÚN!#REF! -> #REF! | J20: =+CANCÚN!#REF! -> #REF! | K20: =+CANCÚN!#REF! -> #REF! | M20: =+AVERAGE(J20,I20,K20) -> #REF! | O20: =+M20/$M$24 -> #REF!
B21: 102419 | C21: CRINKLE CUT PREMIER GOLD 12MM 4X2.5KG | D21: 64 | E21: =+CANCÚN!J18 -> 0 | F21: =+CANCÚN!#REF! -> #REF! | G21: =+CANCÚN!#REF! -> #REF! | H21: =+CANCÚN!#REF! -> #REF! | I21: =+CANCÚN!#REF! -> #REF! | J21: =+CANCÚN!#REF! -> #REF! | K21: =+CANCÚN!#REF! -> #REF! | M21: =+AVERAGE(J21,I21,K21) -> #REF! | O21: =+M21/$M$24 -> #REF!
B22: 105632 | C22: straight cut 10 mm 4/2500 PRMOCIÓN | E22: =+CANCÚN!J19 -> 33 | F22: =+CANCÚN!#REF! -> #REF! | G22: =+CANCÚN!#REF! -> #REF! | H22: =+CANCÚN!#REF! -> #REF! | I22: =+CANCÚN!#REF! -> #REF! | J22: =+CANCÚN!#REF! -> #REF! | K22: =+CANCÚN!#REF! -> #REF! | M22: =+AVERAGE(J22,I22,K22) -> #REF! | O22: =+M22/$M$24 -> #REF!
B23: TOTAL WERNSING | D23: =+SUM(D14:D22) -> 2129.25 | E23: =+SUM(E14:E22) -> #REF! | F23: =+SUM(F14:F22) -> #REF! | G23: =+SUM(G14:G22) -> #REF! | H23: =+SUM(H14:H22) -> #REF! | I23: =+SUM(I14:I22) -> #REF! | J23: =+SUM(J14:J22) -> #REF! | K23: =+SUM(K14:K22) -> #REF! | M23: =+SUM(M14:M22) -> #REF! | O23: =SUM(O14:O22) -> #REF!
B24: TOTAL ABASTOS LOGICOS | D24: =+D23+D13 -> 2337 | E24: =+E23+E13 -> #REF! | F24: =+F23+F13 -> #REF! | G24: =+G23+G13 -> #REF! | H24: =+H23+H13 -> #REF! | I24: =+I23+I13 -> #REF! | J24: =+J23+J13 -> #REF! | K24: =+K23+K13 -> #REF! | M24: =+M23+M13 -> #REF! | O24: =+O23+O13 -> #REF!
A25: MEXIDELI | FRIGARSA | CANBELT | B25: CÓDIGO | C25: DESCRIPCIÓN
B26: 806685 | C26: AVIKO H PREM.CRUNCH SHOESTRING 7MM 4X2270G | D26: 1362 | E26: =+'RESUMEN CDMX'!#REF!+#REF! -> #REF! | F26: =+'RESUMEN CDMX'!#REF!+#REF! -> #REF! | G26: =+'RESUMEN CDMX'!#REF!+#REF! -> #REF! | H26: =+'RESUMEN CDMX'!#REF!+#REF! -> #REF! | I26: =+'RESUMEN CDMX'!#REF!+#REF! -> #REF! | J26: =+'RESUMEN CDMX'!#REF!+#REF! -> #REF! | K26: =+'RESUMEN CDMX'!#REF!+#REF! -> #REF! | M26: =+AVERAGE(J26,I26,K26) -> #REF! | O26: =+M26/$M$44 -> #REF!
B27: 806939 | C27: AVIKO CRINKLE CUT 12MM 4 X 2.5 KG | D27: 179 | E27: =+'RESUMEN CDMX'!#REF!+#REF!+#REF! -> #REF! | F27: =+'RESUMEN CDMX'!#REF!+#REF!+#REF! -> #REF! | G27: =+'RESUMEN CDMX'!#REF!+#REF!+#REF! -> #REF! | H27: =+'RESUMEN CDMX'!#REF!+#REF!+#REF! -> #REF! | I27: =+'RESUMEN CDMX'!#REF!+#REF!+#REF! -> #REF! | J27: =+'RESUMEN CDMX'!#REF!+#REF!+#REF! -> #REF! | K27: =+'RESUMEN CDMX'!#REF!+#REF!+#REF! -> #REF! | M27: =+AVERAGE(J27,I27,K27) -> #REF! | O27: =+M27/$M$44 -> #REF!
B28: 806694 | C28: AVIKO SUPER CRUNCH 9.5mm 3/8 4x2500g | E28: =+'RESUMEN CDMX'!#REF!+#REF! -> #REF! | F28: =+'RESUMEN CDMX'!#REF!+#REF! -> #REF! | G28: =+'RESUMEN CDMX'!#REF!+#REF! -> #REF! | H28: =+'RESUMEN CDMX'!#REF!+#REF! -> #REF! | I28: =+'RESUMEN CDMX'!#REF!+#REF! -> #REF! | J28: =+'RESUMEN CDMX'!#REF!+#REF! -> #REF! | K28: =+'RESUMEN CDMX'!#REF!+#REF! -> #REF! | M28: =+AVERAGE(J28,I28,K28) -> #REF! | O28: =+M28/$M$44 -> #REF!
B29: 802142 | C29: AVIKO STRAIGHT CUT 3/8 | E29: =+'RESUMEN CDMX'!#REF!+#REF! -> #REF! | F29: =+'RESUMEN CDMX'!#REF!+#REF! -> #REF! | G29: =+'RESUMEN CDMX'!#REF!+#REF! -> #REF! | H29: =+'RESUMEN CDMX'!#REF!+#REF! -> #REF! | I29: =+'RESUMEN CDMX'!#REF!+#REF! -> #REF! | J29: =+'RESUMEN CDMX'!#REF!+#REF! -> #REF! | K29: =+'RESUMEN CDMX'!#REF!+#REF! -> #REF! | M29: =+AVERAGE(J29,I29,K29) -> #REF! | O29: =+M29/$M$44 -> #REF!
B30: 804104 | C30: HASHBROWN TRIANGULOS | E30: =+'RESUMEN CDMX'!#REF!+#REF! -> #REF! | F30: =+'RESUMEN CDMX'!#REF!+#REF! -> #REF! | G30: =+'RESUMEN CDMX'!#REF!+#REF! -> #REF! | H30: =+'RESUMEN CDMX'!#REF!+#REF! -> #REF! | I30: =+'RESUMEN CDMX'!#REF!+#REF! -> #REF! | J30: =+'RESUMEN CDMX'!#REF!+#REF! -> #REF! | K30: =+'RESUMEN CDMX'!#REF!+#REF! -> #REF! | M30: =+AVERAGE(J30,I30,K30) -> #REF! | O30: =+M30/$M$44 -> #REF!
B31: 801754 | C31: AVIKO GRATINS MUSHROONS | E31: =+'RESUMEN CDMX'!#REF!+#REF! -> #REF! | F31: =+'RESUMEN CDMX'!#REF!+#REF! -> #REF! | G31: =+'RESUMEN CDMX'!#REF!+#REF! -> #REF! | H31: =+'RESUMEN CDMX'!#REF!+#REF! -> #REF! | I31: =+'RESUMEN CDMX'!#REF!+#REF! -> #REF! | J31: =+'RESUMEN CDMX'!#REF!+#REF! -> #REF! | K31: =+'RESUMEN CDMX'!#REF!+#REF! -> #REF! | M31: =+AVERAGE(J31,I31,K31) -> #REF! | O31: =+M31/$M$44 -> #REF!
B32: 807057 | C32: AVIKO MINI GRATINS | E32: =+'RESUMEN CDMX'!#REF!+#REF! -> #REF! | F32: =+'RESUMEN CDMX'!#REF!+#REF! -> #REF! | G32: =+'RESUMEN CDMX'!#REF!+#REF! -> #REF! | H32: =+'RESUMEN CDMX'!#REF!+#REF! -> #REF! | I32: =+'RESUMEN CDMX'!#REF!+#REF! -> #REF! | J32: =+'RESUMEN CDMX'!#REF!+#REF! -> #REF! | K32: =+'RESUMEN CDMX'!#REF!+#REF! -> #REF! | M32: =+AVERAGE(J32,I32,K32) -> #REF! | O32: =+M32/$M$44 -> #REF!
B33: 807677 | C33: AVIKO WAFFLE CUT 5X1500G | E33: =+'RESUMEN CDMX'!#REF!+#REF! -> #REF! | F33: =+'RESUMEN CDMX'!#REF!+#REF! -> #REF! | G33: =+'RESUMEN CDMX'!#REF!+#REF! -> #REF! | H33: =+'RESUMEN CDMX'!#REF!+#REF! -> #REF! | I33: =+'RESUMEN CDMX'!#REF!+#REF! -> #REF! | J33: =+'RESUMEN CDMX'!#REF!+#REF! -> #REF! | K33: =+'RESUMEN CDMX'!#REF!+#REF! -> #REF! | M33: =+AVERAGE(J33,I33,K33) -> #REF! | O33: =+M33/$M$44 -> #REF!
B34: 806686 | C34: AVIKO H PREM CRUNCH 9.5 mm 3/8 4x2270g | D34: 18 | E34: =+'RESUMEN CDMX'!#REF!+#REF! -> #REF! | F34: =+'RESUMEN CDMX'!#REF!+#REF! -> #REF! | G34: =+'RESUMEN CDMX'!#REF!+#REF! -> #REF! | H34: =+'RESUMEN CDMX'!#REF!+#REF! -> #REF! | I34: =+'RESUMEN CDMX'!#REF!+#REF! -> #REF! | J34: =+'RESUMEN CDMX'!#REF!+#REF! -> #REF! | K34: =+'RESUMEN CDMX'!#REF!+#REF! -> #REF! | M34: =+AVERAGE(J34,I34,K34) -> #REF! | O34: =+M34/$M$44 -> #REF!
B35: 804109 | C35: AVIKO SHOESTRING 5x2500g | D35: 35 | E35: =+'RESUMEN CDMX'!#REF!+#REF! -> #REF! | F35: =+'RESUMEN CDMX'!#REF!+#REF! -> #REF! | G35: =+'RESUMEN CDMX'!#REF!+#REF! -> #REF! | H35: =+'RESUMEN CDMX'!#REF!+#REF! -> #REF! | I35: =+'RESUMEN CDMX'!#REF!+#REF! -> #REF! | J35: =+'RESUMEN CDMX'!#REF!+#REF! -> #REF! | K35: =+'RESUMEN CDMX'!#REF!+#REF! -> #REF! | M35: =+AVERAGE(J35,I35,K35) -> #REF! | O35: =+M35/$M$44 -> #REF!
B36: 806982 | C36: AVIKO BREADED ONION RINGS 6x1000g | E36: =+'RESUMEN CDMX'!#REF!+#REF! -> #REF! | F36: =+'RESUMEN CDMX'!#REF!+#REF! -> #REF! | G36: =+'RESUMEN CDMX'!#REF!+#REF! -> #REF! | H36: =+'RESUMEN CDMX'!#REF!+#REF! -> #REF! | I36: =+'RESUMEN CDMX'!#REF!+#REF! -> #REF! | J36: =+'RESUMEN CDMX'!#REF!+#REF! -> #REF! | K36: =+'RESUMEN CDMX'!#REF!+#REF! -> #REF! | M36: =+AVERAGE(J36,I36,K36) -> #REF! | O36: =+M36/$M$44 -> #REF!
B37: 806980 | C37: AVIKO SPICY JACKET WEDGES 4x2500g | D37: 99 | E37: =+'RESUMEN CDMX'!#REF!+#REF! -> #REF! | F37: =+'RESUMEN CDMX'!#REF!+#REF! -> #REF! | G37: =+'RESUMEN CDMX'!#REF!+#REF! -> #REF! | H37: =+'RESUMEN CDMX'!#REF!+#REF! -> #REF! | I37: =+'RESUMEN CDMX'!#REF!+#REF! -> #REF! | J37: =+'RESUMEN CDMX'!#REF!+#REF! -> #REF! | K37: =+'RESUMEN CDMX'!#REF!+#REF! -> #REF! | M37: =+AVERAGE(J37,I37,K37) -> #REF! | O37: =+M37/$M$44 -> #REF!
B38: 807366 | C38: AVIKO STRAIGHT CHURROS 6x1000g | E38: =+'RESUMEN CDMX'!#REF!+#REF! -> #REF! | F38: =+'RESUMEN CDMX'!#REF!+#REF! -> #REF! | G38: =+'RESUMEN CDMX'!#REF!+#REF! -> #REF! | H38: =+'RESUMEN CDMX'!#REF!+#REF! -> #REF! | I38: =+'RESUMEN CDMX'!#REF!+#REF! -> #REF! | J38: =+'RESUMEN CDMX'!#REF!+#REF! -> #REF! | K38: =+'RESUMEN CDMX'!#REF!+#REF! -> #REF! | M38: =+AVERAGE(J38,I38,K38) -> #REF! | O38: =+M38/$M$44 -> #REF!
B39: 260612 | C39: CASTEL STRAIGHT CUT FRIES 4X2500g | D39: 755 | E39: =+'RESUMEN CDMX'!#REF!+#REF! -> #REF! | F39: =+'RESUMEN CDMX'!#REF!+#REF! -> #REF! | G39: =+'RESUMEN CDMX'!#REF!+#REF! -> #REF! | H39: =+'RESUMEN CDMX'!#REF!+#REF! -> #REF! | I39: =+'RESUMEN CDMX'!#REF!+#REF! -> #REF! | J39: =+'RESUMEN CDMX'!#REF!+#REF! -> #REF! | K39: =+'RESUMEN CDMX'!#REF!+#REF! -> #REF! | M39: =+AVERAGE(J39,I39,K39) -> #REF! | O39: =+M39/$M$44 -> #REF!
B40: 804661 | C40: AVIKO STEAK FRIES 4X2500G 4X5.5 LBS | D40: 167 | E40: =+'RESUMEN CDMX'!#REF!+#REF! -> #REF! | F40: =+'RESUMEN CDMX'!#REF!+#REF! -> #REF! | G40: =+'RESUMEN CDMX'!#REF!+#REF! -> #REF! | H40: =+'RESUMEN CDMX'!#REF!+#REF! -> #REF! | I40: =+'RESUMEN CDMX'!#REF!+#REF! -> #REF! | J40: =+'RESUMEN CDMX'!#REF!+#REF! -> #REF! | K40: =+'RESUMEN CDMX'!#REF!+#REF! -> #REF! | M40: =+AVERAGE(J40,I40,K40) -> #REF! | O40: =+M40/$M$44 -> #REF!
...

Sheet Resumen T.C.
A1: Fecha | B1: Valor USD DOF | C1: Valor EUR Banco de México | D1: Valor EUR Investing | E1: Hora | F1: prom m¿del mes | G1: prom 10 dias | H1: prom5dias
A2: 45748 | B2: 20.438 | C2: 21.9864 | D2: 21.9517 | E2: 0.54166667
A3: 45749 | B3: 20.3587 | C3: 22.0821 | D3: 22.0433 | E3: 0.58333333
A4: 45750 | B4: 20.4568 | C4: 22.0707 | D4: 22.0603 | E4: 0.625
A5: 45751 | B5: 19.9708 | C5: 22.6106 | D5: 22.3884 | E5: 0.45833333
A6: 45754 | B6: 20.501 | C6: 22.6804 | D6: 22.5624 | E6: 0.58333333
A7: 45755 | B7: 20.6947 | C7: 22.6075 | D7: 22.9315 | E7: 0.625
A8: 45756 | B8: 20.6867 | C8: 22.9072 | D8: 22.2754 | E8: 0.66666667
A9: 45757 | B9: 20.7653 | C9: 22.7041 | D9: 23.3045 | E9: 0.70833333
A10: 45758 | B10: 20.492 | C10: 23.042 | D10: 23.07 | E10: 0.62847222
A11: 45761.043 | B11: 20.3363 | C11: 22.8907 | D11: 22.8368 | E11: 12.52 pm
A12: 45762 | B12: 20.1025 | C12: 22.7092 | D12: 22.5984 | E12: 12
A13: 45763 | B13: 20.0213 | C13: 22.69313 | D13: 22.7157 | E13: 12
A14: 45764 | D14: 22.4674 | E14: 15 | F14: =AVERAGE(D2:D15) -> 22.558257 | G14: =AVERAGE(D5:D15) -> 22.705482 | H14: =AVERAGE(D10:D14) -> 22.73766 | I14: =AVERAGE(F14:H14) -> 22.667133
A15: 45768 | D15: 22.6098 | E15: 0.33333333
A16: 45769 | D16: 22.3985 | E16: 11.45 am | F16: =AVERAGE(D2:D16) -> 22.547607 | G16: =AVERAGE(D7:D16) -> 22.7208 | H16: =AVERAGE(D12:D16) -> 22.55796 | I16: =AVERAGE(F16:H16) -> 22.608789
A17: 23 | D17: 22.26 | E17: 1.40 pm | F17: =AVERAGE(D2:D17) -> 22.529631 | G17: =AVERAGE(D8:D17) -> 22.65365 | H17: =AVERAGE(D13:D17) -> 22.49028 | I17: =AVERAGE(F17:H17) -> 22.557854
F18: =AVERAGE(D2:D18) -> 22.529631 | G18: =AVERAGE(D9:D18) -> 22.695678 | H18: =AVERAGE(D14:D18) -> 22.433925 | I18: =AVERAGE(F18:H18) -> 22.553078
A20: PROMEDIOS | B20: =+AVERAGE(B2:B13) -> 20.402008 | C20: =+AVERAGE(C2:C13) -> 22.582003 | D20: =+AVERAGE(D2:D14) -> 22.554292 | E20: =+AVERAGE(E2:E10) -> 0.60223765

Sheet CANCÚN
O1: 30 | BO1: INV ACTUAL + CONTENEDORES EN TRANSITO - VENTAS | BR1: Consumo mensual, Promedio año en curso | BS1: Proyeccion de Ventas, con 10% al promedio del consumo mensual | BT1: Duracion de Inv. En Meses Considerando Inv Actual + Contenedores en Transito - Ventas | BX1: CONTENEDORES EN TRANSITO | CA1: Cjas x Tarima | CB1: SUGERENCIA DE PEDIDOS, DE CONTENEDOR A 21 PALLET
A2: PROMEDIO DÍAS DE TRANSITO | B2: PROVEEDOR | C2: ESTATUS DEL PRODUCTO | D2: CÓDIGO | E2: DESCRIPCIÓN | F2: INV DICIEMBRE 2025 | G2: COMPRAS | H2: Entradas | I2: Salidas | J2: VENTAS | K2: INV ENERO 2026 | L2: COMPRAS | M2: Entradas | N2: Salidas | O2: VENTAS | P2: INV FEBRERO 2026 | Q2: COMPRAS | R2: Entradas | S2: Salidas | T2: VENTAS | U2: INV MARZO 2026 | V2: COMPRAS | W2: Entradas | X2: Salidas | Y2: VENTAS | Z2: INV ABRIL 2026 | AA2: COMPRAS | AB2: Entradas | AC2: Salidas | AD2: VENTAS | AE2: INV MAYO 2026 | AF2: COMPRAS | AG2: Entradas | AH2: Salidas | AI2: VENTAS | AJ2: INV JUNIO 2026 | AK2: COMPRAS | AL2: Entradas | AM2: Salidas | AN2: VENTAS | AO2: INV JULIO 2026 | AP2: COMPRAS | AQ2: Entradas | AR2: Salidas | AS2: VENTAS | AT2: INV AGOSTO 2026 | AU2: COMPRAS | AV2: Entradas | AW2: Salidas | AX2: VENTAS | AY2: INV SEPTIEMBRE 2026 | AZ2: COMPRAS | BA2: Entradas | BB2: Salidas | BC2: VENTAS | BD2: INV OCTUBRE 2026 | BE2: COMPRAS | BF2: Entradas | BG2: Salidas | BH2: VENTAS | BI2: INV NOVIEMBRE 2026 | BJ2: COMPRAS | BK2: Entradas | BL2: Salidas | BM2: VENTAS | BN2: INV DICIEMBRE 2026 | BT2: ACTUAL | CB2: PALLET | CC2: CAJAS
A3: 60 | B3: AVIKO | C3: OPORTUNIDAD | D3: 804104 | E3: TRIANGLE HASHBROW 63G/40PZ BAG APPROX) 4 X 2.5KG | F3: 549.5 | J3: 56.25 | K3: =+F3+G3+H3-I3-J3 -> 493.25 | O3: 234.25 | P3: =+K3+L3+M3-N3-O3 -> 259 | T3: 155.75 | U3: =+P3+Q3+R3-S3-T3 -> 103.25 | Y3: 44 | Z3: =+U3+V3+W3-X3-Y3 -> 59.25 | AD3: 24.25 | AE3: =+Z3+AA3+AB3-AC3-AD3 -> 35 | BO3: =IF((AE3-($BR3*(NETWORKDAYS(TODAY(),$BX$12)/$O$1))+BX3)<=0,0,AE3-($BR3*(NETWORKDAYS(TODAY(),$BX$12)/$O$1))+BX3) -> 20.475 | BR3: =AVERAGE(J3,O3) -> 145.25 | BS3: =+BR3*1.1 -> 159.775 | BT3: =+Z3/BR3 -> 0.40791738 | CA3: 108 | CC3: =+CB3*CA3 -> 0
A4: 60 | B4: AVIKO | C4: OPORTUNIDAD | D4: 805567 | E4: HASBROWNS ROUNDS - FRYER 4X2500G | F4: 743.5 | K4: =+F4+G4+H4-I4-J4 -> 743.5 | P4: =+K4+L4+M4-N4-O4 -> 743.5 | R4: 10 | T4: 287.25 | U4: =+P4+Q4+R4-S4-T4 -> 466.25 | W4: 1 | Y4: 319 | Z4: =+U4+V4+W4-X4-Y4 -> 148.25 | AB4: 9 | AD4: 46 | AE4: =+Z4+AA4+AB4-AC4-AD4 -> 111.25 | BO4: =IF((AE4-($BR4*(NETWORKDAYS(TODAY(),$BX$12)/$O$1))+BX4)<=0,0,AE4-($BR4*(NETWORKDAYS(TODAY(),$BX$12)/$O$1))+BX4) -> 86.25 | BR4: 250 | BS4: =+BR4*1.1 -> 275 | BT4: =+Z4/BR4 -> 0.593 | CA4: 108 | CC4: =+CB4*CA4 -> 0
A5: 60 | B5: AVIKO | C5: INACTIVO | D5: 803528 | E5: Aviko H Pommes Frites 11mm 7/16 4x2500g | F5: 0 | K5: =+F5+G5+H5-I5-J5 -> 0 | P5: =+K5+L5+M5-N5-O5 -> 0 | AE5: =+Z5+AA5+AB5-AC5-AD5 -> 0 | BO5: =IF((AE5-($BR5*(NETWORKDAYS(TODAY(),$BX$12)/$O$1))+BX5)<=0,0,AE5-($BR5*(NETWORKDAYS(TODAY(),$BX$12)/$O$1))+BX5) -> 0 | CA5: 108 | CC5: =+CB5*CA5 -> 0
A6: 60 | B6: AVIKO | C6: INACTIVO | D6: 806685 | E6: AVIKO H PREM.CRUNCH SHOESTRING 7MM 4X2270G | F6: 51.25 | J6: 51 | K6: =+F6+G6+H6-I6-J6 -> 0.25 | O6: 0.25 | P6: =+K6+L6+M6-N6-O6 -> 0 | AE6: =+Z6+AA6+AB6-AC6-AD6 -> 0 | BO6: =IF((AE6-($BR6*(NETWORKDAYS(TODAY(),$BX$12)/$O$1))+BX6)<=0,0,AE6-($BR6*(NETWORKDAYS(TODAY(),$BX$12)/$O$1))+BX6) -> 0 | BR6: 2.25 | BT6: =+P6/BR6 -> 0 | CA6: 108 | CC6: =+CB6*CA6 -> 0
K7: =+F7+G7+H7-I7-J7 -> 0
K8: =+F8+G8+H8-I8-J8 -> 0
K9: =+F9+G9+H9-I9-J9 -> 0
D10: TOTAL AVIKO | F10: =+SUM(F3:F9) -> 1344.25 | G10: =+SUM(G3:G9) -> 0 | H10: =+SUM(H3:H9) -> 0 | I10: =+SUM(I3:I9) -> 0 | J10: =+SUM(J3:J9) -> 107.25 | K10: =+SUM(K3:K9) -> 1237 | L10: =+SUM(L3:L9) -> 0 | M10: =+SUM(M3:M9) -> 0 | ... S10: =+SUM(S3:S9) -> 0 | T10: =SUM(T3:T5) -> 443 | U10: =+SUM(U3:U9) -> 569.5 | V10: =+SUM(V3:V9) -> 0 | W10: =+SUM(W3:W9) -> 1 | X10: =+SUM(X3:X9) -> 0 | Y10: =+SUM(Y3:Y9) -> 363 | Z10: =+SUM(Z3:Z9) -> 207.5 | AA10: =+SUM(AA3:AA9) -> 0 | AB10: =+SUM(AB3:AB9) -> 9 | ... BN10: =+SUM(BN3:BN9) -> 0 | BR10: =SUM(BR3:BR6) -> 397.5 | BS10: =SUM(BS3:BS6) -> 434.775 | BX10: =+SUM(BX3:BX6) -> 0 | CB10: =+SUM(CB3:CB6) -> 0 | CC10: =+SUM(CC3:CC6) -> 0
BO11: INV ACTUAL + CONTENEDORES EN TRANSITO - VENTAS | BR11: Consumo mensual, Promedio año en curso | BS11: Proyeccion de Ventas, con 10% al promedio del consumo mensual | BT11: Duracion de Inv. En Meses Considerando Inv Actual + Contenedores en Transito - Ventas | BX11: C-112 PTO 13-05 | BY11: C-114 PTO 13-05 | BZ11: SUGERIDO | CB11: SUGERENCIA DE PEDIDOS, DE CONTENEDOR A 21 PALLET
A12: PROMEDIO DÍAS DE TRANSITO | B12: PROVEEDOR | C12: ESTATUS DEL PRODUCTO | D12: CÓDIGO | E12: DESCRIPCIÓN | F12: INV DICIEMBRE 2025 | G12: COMPRAS | H12: Entradas | I12: Salidas | J12: VENTAS | K12: INV ENERO 2026 | L12: COMPRAS | M12: Entradas | N12: Salidas | O12: VENTAS | P12: INV FEBRERO 2026 | Q12: COMPRAS | R12: Entradas | S12: Salidas | T12: VENTAS | U12: INV MARZO 2026 | V12: COMPRAS | W12: Entradas | X12: Salidas | Y12: VENTAS | Z12: INV ABRIL 2026 | AA12: COMPRAS | AB12: Entradas | AC12: Salidas | AD12: VENTAS | AE12: INV MAYO 2026 | AF12: COMPRAS | AG12: Entradas | AH12: Salidas | AI12: VENTAS | AJ12: INV JUNIO 2026 | AK12: COMPRAS | AL12: Entradas | AM12: Salidas | AN12: VENTAS | AO12: INV JULIO 2026 | AP12: COMPRAS | AQ12: Entradas | AR12: Salidas | AS12: VENTAS | AT12: INV AGOSTO 2026 | AU12: COMPRAS | AV12: Entradas | AW12: Salidas | AX12: VENTAS | AY12: INV SEPTIEMBRE 2026 | AZ12: COMPRAS | BA12: Entradas | BB12: Salidas | BC12: VENTAS | BD12: INV OCTUBRE 2026 | BE12: COMPRAS | BF12: Entradas | BG12: Salidas | BH12: VENTAS | BI12: INV NOVIEMBRE 2026 | BJ12: COMPRAS | BK12: Entradas | BL12: Salidas | BM12: VENTAS | BN12: INV DICIEMBRE 2026 | BO12: C-112 | BP12: C-114 | BT12: ACTUAL | BU12: 112 | BV12: 114 | BW12: SUGERIDO | BX12: 46158 | BY12: 46158 | BZ12: 46192 | CB12: PALLET | CC12: CAJAS
A13: 60 | B13: WERSING | C13: ACTIVO | D13: 105632 | E13: 10 MM NATURAL, MISMO PRODUCTO 102013 | F13: 0 | H13: 4371 | J13: 1083.25 | K13: =+F13+G13+H13-I13-J13 -> 3287.75 | O13: 919.75 | P13: =+K13+L13+M13-N13-O13 -> 2368 | T13: 1621.25 | U13: =+P13+Q13+R13-S13-T13 -> 746.75 | Y13: 746.75 | Z13: =+U13+V13+W13-X13-Y13 -> 0 | AE13: =+Z13+AA13+AB13-AC13-AD13 -> 0 | BO13: =IF((AE13-($BR13*(NETWORKDAYS(TODAY(),$BX$12)/$O$1))+BX13)<=0,0,AE13-($BR13*(NETWORKDAYS(TODAY(),$BX$12)/$O$1))+BX13) -> 0 | BP13: =IF((BO13-($BR13*(NETWORKDAYS($BX$12,$BY$12)/$O$1))+BY13)<=0,0,BO13-($BR13*(NETWORKDAYS($BX$12,$BY$12)/$O$1))+BY13) -> 0 | BQ13: =IF((BP13-($BR13*(NETWORKDAYS($BY$12,$BZ$12)/$O$1))+BZ13)<=0,0,BP13-($BR13*(NETWORKDAYS($BY$12,$BZ$12)/$O$1))+BZ13) -> 0 | BR13: =AVERAGE(J13,O13,T13,Y13) -> 1092.75 | BT13: =+Z13/BR13 -> 0 | BU13: =+BO13/BR13 -> 0 | BV13: =+BP13/BR13 -> 0 | BW13: =+BQ13/BR13 -> 0 | CA13: 120 | CC13: =+CB13*CA13 -> 0
A14: 60 | B14: WERSING | C14: ACTIVO | D14: 102013 | E14: 10 MM NATURAL, MISMO PRODUCTO 105632 | F14: 1.25 | J14: 1.25 | K14: =+F14+G14+H14-I14-J14 -> 0 | P14: =+K14+L14+M14-N14-O14 -> 0 | U14: =+P14+Q14+R14-S14-T14 -> 0 | W14: 2088 | Y14: 404 | Z14: =+U14+V14+W14-X14-Y14 -> 1684 | AD14: 363.25 | AE14: =+Z14+AA14+AB14-AC14-AD14 -> 1320.75 | BO14: =IF((AE14-($BR14*(NETWORKDAYS(TODAY(),$BX$12)/$O$1))+BX14)<=0,0,AE14-($BR14*(NETWORKDAYS(TODAY(),$BX$12)/$O$1))+BX14) -> 1199.942 | BP14: =IF((BO14-($BR14*(NETWORKDAYS($BX$12,$BY$12)/$O$1))+BY14)<=0,0,BO14-($BR14*(NETWORKDAYS($BX$12,$BY$12)/$O$1))+BY14) -> 2711.942 | BQ14: =IF((BP14-($BR14*(NETWORKDAYS($BY$12,$BZ$12)/$O$1))+BZ14)<=0,0,BP14-($BR14*(NETWORKDAYS($BY$12,$BZ$12)/$O$1))+BZ14) -> 3265.2087 | BR14: 1208.08 | BS14: =+BR14*1.1 -> 1328.888 | BT14: =+AE14/BR14 -> 1.0932637 | BU14: =+BO14/BR14 -> 0.99326369 | BV14: =+BP14/BR14 -> 2.2448364 | BW14: =+BQ14/BR14 -> 2.7028083 | BY14: 1512 | BZ14: 1560 | CA14: 120 | CB14: 13 | CC14: =+CB14*CA14 -> 1560
A15: 60 | B15: WERSING | C15: ACTIVO | D15: 102341 | E15: 10 MM CON COBERTURA | F15: 2340.75 | H15: 216 | J15: 412.25 | K15: =+F15+G15+H15-I15-J15 -> 2144.5 | O15: 514 | P15: =+K15+L15+M15-N15-O15 -> 1630.5 | T15: 610.25 | U15: =+P15+Q15+R15-S15-T15 -> 1020.25 | Y15: 444 | Z15: =+U15+V15+W15-X15-Y15 -> 576.25 | AD15: 26 | AE15: =+Z15+AA15+AB15-AC15-AD15 -> 550.25 | BO15: =IF((AE15-($BR15*(NETWORKDAYS(TODAY(),$BX$12)/$O$1))+BX15)<=0,0,AE15-($BR15*(NETWORKDAYS(TODAY(),$BX$12)/$O$1))+BX15) -> 500.7375 | BP15: =IF((BO15-($BR15*(NETWORKDAYS($BX$12,$BY$12)/$O$1))+BY15)<=0,0,BO15-($BR15*(NETWORKDAYS($BX$12,$BY$12)/$O$1))+BY15) -> 500.7375 | BQ15: =IF((BP15-($BR15*(NETWORKDAYS($BY$12,$BZ$12)/$O$1))+BZ15)<=0,0,BP15-($BR15*(NETWORKDAYS($BY$12,$BZ$12)/$O$1))+BZ15) -> 88.133333 | BR15: =AVERAGE(J15,O15,T15,Y15) -> 495.125 | BS15: =+BR15*1.1 -> 544.6375 | BT15: =+AE15/BR15 -> 1.1113355 | BU15: =+BO15/BR15 -> 1.0113355 | BV15: =+BP15/BR15 -> 1.0113355 | BW15: =+BQ15/BR15 -> 0.17800219 | CA15: 108 | CC15: =+CB15*CA15 -> 0
A16: 60 | B16: WERSING | C16: ACTIVO | D16: 102310 | E16: 7 MM CON COBERTURA | F16: 124 | J16: 25 | K16: =+F16+G16+H16-I16-J16 -> 99 | O16: 32.5 | P16: =+K16+L16+M16-N16-O16 -> 66.5 | T16: 27.75 | U16: =+P16+Q16+R16-S16-T16 -> 38.75 | W16: 126 | Y16: 30 | Z16: =+U16+V16+W16-X16-Y16 -> 134.75 | AD16: 11 | AE16: =+Z16+AA16+AB16-AC16-AD16 -> 123.75 | BO16: =IF((AE16-($BR16*(NETWORKDAYS(TODAY(),$BX$12)/$O$1))+BX16)<=0,0,AE16-($BR16*(NETWORKDAYS(TODAY(),$BX$12)/$O$1))+BX16) -> 120.86875 | BP16: =IF((BO16-($BR16*(NETWORKDAYS($BX$12,$BY$12)/$O$1))+BY16)<=0,0,BO16-($BR16*(NETWORKDAYS($BX$12,$BY$12)/$O$1))+BY16) -> 120.86875 | BQ16: =IF((BP16-($BR16*(NETWORKDAYS($BY$12,$BZ$12)/$O$1))+BZ16)<=0,0,BP16-($BR16*(NETWORKDAYS($BY$12,$BZ$12)/$O$1))+BZ16) -> 96.858333 | BR16: =AVERAGE(J16,O16,T16,Y16) -> 28.8125 | BS16: =+BR16*1.1 -> 31.69375 | BT16: =+AE16/BR16 -> 4.2950108 | BU16: =+BO16/BR16 -> 4.1950108 | BV16: =+BP16/BR16 -> 4.1950108 | BW16: =+BQ16/BR16 -> 3.3616775 | CA16: 108 | CC16: =+CB16*CA16 -> 0
A17: 60 | B17: WERSING | D17: 102211 | E17: 7 MM NATURAL | F17: 0 | K17: =+F17+G17+H17-I17-J17 -> 0 | P17: =+K17+L17+M17-N17-O17 -> 0 | U17: =+P17+Q17+R17-S17-T17 -> 0 | Z17: =+U17+V17+W17-X17-Y17 -> 0 | AE17: =+Z17+AA17+AB17-AC17-AD17 -> 0 | BO17: =IF((AE17-($BR17*(NETWORKDAYS(TODAY(),$BX$12)/$O$1))+BX17)<=0,0,AE17-($BR17*(NETWORKDAYS(TODAY(),$BX$12)/$O$1))+BX17) -> #DIV/0! | BP17: =IF((BO17-($BR17*(NETWORKDAYS($BX$12,$BY$12)/$O$1))+BY17)<=0,0,BO17-($BR17*(NETWORKDAYS($BX$12,$BY$12)/$O$1))+BY17) -> #DIV/0! | BQ17: =IF((BP17-($BR17*(NETWORKDAYS($BY$12,$BZ$12)/$O$1))+BZ17)<=0,0,BP17-($BR17*(NETWORKDAYS($BY$12,$BZ$12)/$O$1))+BZ17) -> #DIV/0! | BR17: =AVERAGE(J17,O17,T17,Y17) -> #DIV/0! | BS17: =+BR17*1.1 -> #DIV/0! | BT17: =+AE17/BR17 -> #DIV/0! | BU17: =+BO17/BR17 -> #DIV/0! | BV17: =+BP17/BR17 -> #DIV/0! | BW17: =+BQ17/BR17 -> #DIV/0! | CA17: 108 | CC17: =+CB17*CA17 -> 0
A18: 60 | B18: WERSING | D18: 104215 | E18: 10 MM CON COBERTURA Y CASCARA | F18: 0 | K18: =+F18+G18+H18-I18-J18 -> 0 | P18: =+K18+L18+M18-N18-O18 -> 0 | U18: =+P18+Q18+R18-S18-T18 -> 0 | Z18: =+U18+V18+W18-X18-Y18 -> 0 | AE18: =+Z18+AA18+AB18-AC18-AD18 -> 0 | BO18: =IF((AE18-($BR18*(NETWORKDAYS(TODAY(),$BX$12)/$O$1))+BX18)<=0,0,AE18-($BR18*(NETWORKDAYS(TODAY(),$BX$12)/$O$1))+BX18) -> #DIV/0! | BP18: =IF((BO18-($BR18*(NETWORKDAYS($BX$12,$BY$12)/$O$1))+BY18)<=0,0,BO18-($BR18*(NETWORKDAYS($BX$12,$BY$12)/$O$1))+BY18) -> #DIV/0! | BQ18: =IF((BP18-($BR18*(NETWORKDAYS($BY$12,$BZ$12)/$O$1))+BZ18)<=0,0,BP18-($BR18*(NETWORKDAYS($BY$12,$BZ$12)/$O$1))+BZ18) -> #DIV/0! | BR18: =AVERAGE(J18,O18,T18,Y18) -> #DIV/0! | BS18: =+BR18*1.1 -> #DIV/0! | BT18: =+AE18/BR18 -> #DIV/0! | BU18: =+BO18/BR18 -> #DIV/0! | BV18: =+BP18/BR18 -> #DIV/0! | BW18: =+BQ18/BR18 -> #DIV/0! | CA18: 144 | CC18: =+CB18*CA18 -> 0
A19: 60 | B19: WERSING | C19: ACTIVO | D19: 114054 | E19: GAJOS SAZONADOS | F19: 519.25 | J19: 33 | K19: =+F19+G19+H19-I19-J19 -> 486.25 | O19: 38.5 | P19: =+K19+L19+M19-N19-O19 -> 447.75 | T19: 27 | U19: =+P19+Q19+R19-S19-T19 -> 420.75 | Y19: 29.25 | Z19: =+U19+V19+W19-X19-Y19 -> 391.5 | AD19: 7 | AE19: =+Z19+AA19+AB19-AC19-AD19 -> 384.5 | BO19: =IF((AE19-($BR19*(NETWORKDAYS(TODAY(),$BX$12)/$O$1))+BX19)<=0,0,AE19-($BR19*(NETWORKDAYS(TODAY(),$BX$12)/$O$1))+BX19) -> 381.30625 | BP19: =IF((BO19-($BR19*(NETWORKDAYS($BX$12,$BY$12)/$O$1))+BY19)<=0,0,BO19-($BR19*(NETWORKDAYS($BX$12,$BY$12)/$O$1))+BY19) -> 381.30625 | BQ19: =IF((BP19-($BR19*(NETWORKDAYS($BY$12,$BZ$12)/$O$1))+BZ19)<=0,0,BP19-($BR19*(NETWORKDAYS($BY$12,$BZ$12)/$O$1))+BZ19) -> 354.69167 | BR19: =AVERAGE(J19,O19,T19,Y19) -> 31.9375 | BS19: =+BR19*1.1 -> 35.13125 | BT19: =+AE19/BR19 -> 12.039139 | BU19: =+BO19/BR19 -> 11.939139 | BV19: =+BP19/BR19 -> 11.939139 | BW19: =+BQ19/BR19 -> 11.105806 | CA19: 108 | CC19: =+CB19*CA19 -> 0
A20: 60 | B20: WERSING | C20: ACTIVO | D20: 102419 | E20: ONDULADA | F20: 0 | H20: 180 | J20: 31 | K20: =+F20+G20+H20-I20-J20 -> 149 | O20: 34.25 | P20: =+K20+L20+M20-N20-O20 -> 114.75 | T20: 35.5 | U20: =+P20+Q20+R20-S20-T20 -> 79.25 | W20: 144 | Y20: 41 | Z20: =+U20+V20+W20-X20-Y20 -> 182.25 | AD20: 15.75 | AE20: =+Z20+AA20+AB20-AC20-AD20 -> 166.5 | BO20: =IF((AE20-($BR20*(NETWORKDAYS(TODAY(),$BX$12)/$O$1))+BX20)<=0,0,AE20-($BR20*(NETWORKDAYS(TODAY(),$BX$12)/$O$1))+BX20) -> 162.95625 | BP20: =IF((BO20-($BR20*(NETWORKDAYS($BX$12,$BY$12)/$O$1))+BY20)<=0,0,BO20-($BR20*(NETWORKDAYS($BX$12,$BY$12)/$O$1))+BY20) -> 162.95625 | BQ20: =IF((BP20-($BR20*(NETWORKDAYS($BY$12,$BZ$12)/$O$1))+BZ20)<=0,0,BP20-($BR20*(NETWORKDAYS($BY$12,$BZ$12)/$O$1))+BZ20) -> 133.425 | BR20: =AVERAGE(J20,O20,T20,Y20) -> 35.4375 | BS20: =+BR20*1.1 -> 38.98125 | BT20: =+AE20/BR20 -> 4.6984127 | BU20: =+BO20/BR20 -> 4.5984127 | BV20: =+BP20/BR20 -> 4.5984127 | BW20: =+BQ20/BR20 -> 3.7650794 | CA20: 108 | CC20: =+CB20*CA20 -> 0
A21: 60 | B21: WERSING | D21: 1000440 | E21: 3/8 VIMA FOODS | F21: 113.25 | J21: 110 | K21: =+F21+G21+H21-I21-J21 -> 3.25 | O21: 3.25 | P21: =+K21+L21+M21-N21-O21 -> 0 | U21: =+P21+Q21+R21-S21-T21 -> 0 | Z21: =+U21+V21+W21-X21-Y21 -> 0 | AE21: =+Z21+AA21+AB21-AC21-AD21 -> 0 | BO21: =IF((AE21-($BR21*(NETWORKDAYS(TODAY(),$BX$12)/$O$1))+BX21)<=0,0,AE21-($BR21*(NETWORKDAYS(TODAY(),$BX$12)/$O$1))+BX21) -> 0 | BQ21: =IF((BP21-($BR21*(NETWORKDAYS($BY$12,$BZ$12)/$O$1))+BZ21)<=0,0,BP21-($BR21*(NETWORKDAYS($BY$12,$BZ$12)/$O$1))+BZ21) -> 0 | BR21: =AVERAGE(J21,O21,T21) -> 56.625 | BS21: =+BR21*1.1 -> 62.2875 | BT21: =+AE21/BR21 -> 0 | BU21: =+BO21/BR21 -> 0 | BV21: =+BP21/BR21 -> 0 | BW21: =+BQ21/BR21 -> 0
A22: 60 | B22: WERSING | C22: ACTIVO | D22: 101245 | E22: 11 MM CON COBERTURA, SUSTITUTO 102341 PRODUCTO NUEVO | K22: =+F22+G22+H22-I22-J22 -> 0 | P22: =+K22+L22+M22-N22-O22 -> 0 | U22: =+P22+Q22+R22-S22-T22 -> 0 | Z22: =+U22+V22+W22-X22-Y22 -> 0 | AE22: =+Z22+AA22+AB22-AC22-AD22 -> 0 | BO22: =IF((AE22-($BR22*(NETWORKDAYS(TODAY(),$BX$12)/$O$1))+BX22)<=0,0,AE22-($BR22*(NETWORKDAYS(TODAY(),$BX$12)/$O$1))+BX22) -> 2316 | BP22: =IF((BO22-($BR22*(NETWORKDAYS($BX$12,$BY$12)/$O$1))+BY22)<=0,0,BO22-($BR22*(NETWORKDAYS($BX$12,$BY$12)/$O$1))+BY22) -> 2316 | BQ22: =IF((BP22-($BR22*(NETWORKDAYS($BY$12,$BZ$12)/$O$1))+BZ22)<=0,0,BP22-($BR22*(NETWORKDAYS($BY$12,$BZ$12)/$O$1))+BZ22) -> 1816 | BR22: 600 | BS22: =+BR22*1.1 -> 660 | BT22: =+AE22/BR22 -> 0 | BU22: =+BO22/BR22 -> 3.86 | BV22: =+BP22/BR22 -> 3.86 | BW22: =+BQ22/BR22 -> 3.0266667 | BX22: 2376
A23: 60 | B23: WERSING | C23: ACTIVO | D23: 110582 | E23: TRIANGLE HASHBROW 63G/40PZ BAG APPROX) 4 X 2.5KG, SUSTITUTO 804104 | Z23: =+U23+V23+W23-X23-Y23 -> 0 | AE23: =+Z23+AA23+AB23-AC23-AD23 -> 0 | BO23: =IF((AE23-($BR23*(NETWORKDAYS(TODAY(),$BX$12)/$O$1))+BX23)<=0,0,AE23-($BR23*(NETWORKDAYS(TODAY(),$BX$12)/$O$1))+BX23) -> 0 | BP23: =IF((BO23-($BR23*(NETWORKDAYS($BX$12,$BY$12)/$O$1))+BY23)<=0,0,BO23-($BR23*(NETWORKDAYS($BX$12,$BY$12)/$O$1))+BY23) -> 756 | BQ23: =IF((BP23-($BR23*(NETWORKDAYS($BY$12,$BZ$12)/$O$1))+BZ23)<=0,0,BP23-($BR23*(NETWORKDAYS($BY$12,$BZ$12)/$O$1))+BZ23) -> 979.66667 | BR23: 250 | BS23: =+BR23*1.1 -> 275 | BT23: =+AE23/BR23 -> 0 | BU23: =+BO23/BR23 -> 0 | BV23: =+BP23/BR23 -> 3.024 | BW23: =+BQ23/BR23 -> 3.9186667 | BY23: 756 | BZ23: 432 | CA23: 54 | CB23: 8 | CC23: =+CB23*CA23 -> 432
D24: TOTAL WERNSING | F24: =+SUM(F13:F22) -> 3098.5 | G24: =+SUM(G13:G22) -> 0 | H24: =+SUM(H13:H22) -> 4767 | I24: =+SUM(I13:I22) -> 0 | J24: =+SUM(J13:J22) -> 1695.75 | K24: =+SUM(K13:K22) -> 6169.75 | L24: =+SUM(L13:L22) -> 0 | M24: =+SUM(M13:M22) -> 0 | ... BN24: =+SUM(BN13:BN22) -> 0 | BR24: =+BR13+BR15+BR16+BR19+BR20+BR22 -> 2284.0625 | BS24: =+BS14+BS15+BS16+BS19+BS20+BS22 -> 2639.3317 | BX24: =SUM(BX13:BX22) -> 2376 | BY24: =SUM(BY13:BY23) -> 2268 | BZ24: =SUM(BZ13:BZ23) -> 1992 | CB24: =SUM(CB13:CB23) -> 21 | CC24: =SUM(CC14:CC23) -> 1992
D26: RESUMEN DEL TOTAL DE PAPAS | F26: =+F24+F10 -> 4442.75 | G26: =+G24+G10 -> 0 | H26: =+H24+H10 -> 4767 | I26: =+I24+I10 -> 0 | J26: =+J24+J10 -> 1803 | K26: =+K24+K10 -> 7406.75 | L26: =+L24+L10 -> 0 | M26: =+M24+M10 -> 0 | ... BN26: =+BN24+BN10 -> 0
F27: =+F26/50 -> 88.855 | J27: ESPACIOS | K27: =+K26/50 -> 148.135 | O27: ESPACIOS | P27: =+P26/50 -> 112.6 | T27: ESPACIOS | U27: =+U26/50 -> 57.505 | Y27: ESPACIOS | Z27: =+Z26/BR24 -> 1.3906143 | AD27: ESPACIOS | AE27: =+AE26/50 -> 53.84 | AI27: ESPACIOS | AJ27: =+AJ26/50 -> 0 | AN27: ESPACIOS | AO27: =+AO26/50 -> 0 | AS27: ESPACIOS | AT27: =+AT26/50 -> 0 | AX27: ESPACIOS | AY27: =+AY26/50 -> 0 | BC27: ESPACIOS | BD27: =+BD26/50 -> 0 | BH27: ESPACIOS | BI27: =+BI26/50 -> 0 | BM27: ESPACIOS | BN27: =+BN26/50 -> 0 | BO27: =+AE26/Y26 -> 1.3080661
K28: =+K26/BR24 -> 3.2427966

Sheet RESUMEN CDMX
AI1: CONTENEDORES EN TRANSITO | AK1: SUGERENCIA DE PEDIDOS, DE CONTENEDOR A 21 PALLET
O2: 45 | Z2: INV ACTUAL + CONTENEDORES EN TRANSITO - VENTAS | AC2: VENTAS | AD2: Consumo mensual, Promedio año en curso | AE2: Proyeccion de Ventas, con 10% al promedio del consumo mensual | AF2: Duracion de Inv. En Meses Considerando Inv Actual + Contenedores en Transito - Ventas | AI2: C-426 PTO 31/05 | AJ2: C-429 PTO 20/06 | AK2: Cjas x Tarima
A3: PROMEDIO DÍAS DE TRANSITO | B3: PROVEEDOR | C3: ESTATUS DEL PRODUCTO | D3: CÓDIGO | E3: DESCRIPCIÓN | F3: INV DICIEMBRE 2025 | G3: COMPRAS | H3: Entradas | I3: Salidas | J3: VENTAS | K3: INV ENERO 2026 | L3: COMPRAS | M3: Entradas | N3: Salidas | O3: VENTAS | P3: INV FEB 2026 | Q3: COMPRAS | R3: Entradas | S3: Salidas | T3: VENTAS | U3: INV MAYO ARCOSA 2026 | V3: FRIGARSA | W3: FRESCO | X3: MEXIDELI | Y3: TOTAL CDMX | Z3: ACTUAL | AA3: C-426 | AB3: C-429 | AC3: MAYO | AF3: ACTUAL | AG3: C-426 | AH3: C-429 | AI3: 46178 | AJ3: 46199 | AL3: PALLET | AM3: CAJAS
